<?xml version="1.0"?>
<sdf version="1.7">
<world name="two_acrobots_and_box_world">
  <model name="box">
    <pose>0.3 0.25 0 0 0 0</pose>
    <link name="box">
      <collision name="box_collision">
        <geometry>
          <box>
            <size>0.5 0.5 0.5</size>
          </box>
        </geometry>
        <drake:proximity_properties>
          <drake:dissipation_timescale>0.05</drake:dissipation_timescale>
          <drake:compliant_hydroelastic/>
          <drake:mesh_resolution_hint>0.1</drake:mesh_resolution_hint>
          <drake:hydroelastic_modulus>5e7</drake:hydroelastic_modulus>
        </drake:proximity_properties>
      </collision>
      <visual name="box_visual">
        <geometry>
          <box>
            <size>0.5 0.5 0.5</size>
          </box>
        </geometry>
      </visual>
      <inertial>
        <mass>1.</mass>
        <inertia>
          <ixx>1.0</ixx>
          <ixy>0.0</ixy>
          <ixz>0.0</ixz>
          <iyy>1.0</iyy>
          <iyz>0.0</iyz>
          <izz>1.0</izz>
        </inertia>
      </inertial>
    </link>
  </model>
  <model name="acrobot_one">
    <pose>0 1.0 2.0 0 0 0</pose>
    <link name="base_link">
      <collision name="base_link_collision">
        <geometry>
          <box>
            <size>0.2 0.2 0.2</size>
          </box>
        </geometry>
        <drake:proximity_properties>
          <drake:dissipation_timescale>0.05</drake:dissipation_timescale>
          <drake:compliant_hydroelastic/>
          <drake:mesh_resolution_hint>0.1</drake:mesh_resolution_hint>
          <drake:hydroelastic_modulus>5e7</drake:hydroelastic_modulus>
        </drake:proximity_properties>
      </collision>
      <visual name="base_link_visual">
        <geometry>
          <box>
            <size>0.2 0.2 0.2</size>
          </box>
        </geometry>
      </visual>
    </link>
    <joint name="base_weld" type="fixed">
      <child>base_link</child>
      <parent>world</parent>
    </joint>
    <link name="upper_link">
      <pose>0 0.15 0 0 0 0</pose>
      <inertial>
        <pose>0 0 -0.5 0 0 0</pose>
        <mass>1</mass>
        <inertia>
          <ixx>1</ixx>
          <ixy>0</ixy>
          <ixz>0</ixz>
          <iyy>0.083</iyy>
          <iyz>0</iyz>
          <izz>1</izz>
        </inertia>
      </inertial>
      <collision name="upper_link_collision">
        <pose>0 0 -0.5 0 0 0</pose>
        <geometry>
          <cylinder>
            <length>1.1</length>
            <radius>0.05</radius>
          </cylinder>
        </geometry>
        <drake:proximity_properties>
          <drake:dissipation_timescale>0.05</drake:dissipation_timescale>
          <drake:compliant_hydroelastic/>
          <drake:mesh_resolution_hint>0.05</drake:mesh_resolution_hint>
          <drake:hydroelastic_modulus>5e7</drake:hydroelastic_modulus>
        </drake:proximity_properties>
      </collision>
      <visual name="upper_link_visual">
        <pose>0 0 -0.5 0 0 0</pose>
        <geometry>
          <cylinder>
            <length>1.1</length>
            <radius>0.05</radius>
          </cylinder>
        </geometry>
      </visual>
    </link>
    <joint name="shoulder" type="revolute">
      <child>upper_link</child>
      <parent>base_link</parent>
      <axis>
        <xyz expressed_in="__model__">0 1 0</xyz>
        <limit>
          <effort>0</effort>
        </limit>
        <dynamics>
          <damping>0.1</damping>
          <friction>0</friction>
          <spring_reference>0</spring_reference>
          <spring_stiffness>0</spring_stiffness>
        </dynamics>
      </axis>
    </joint>
    <link name="lower_link">
      <pose>0 0.25 -1 0 0 0</pose>
      <inertial>
        <pose>0 0 -1 0 0 0</pose>
        <mass>1</mass>
        <inertia>
          <ixx>1</ixx>
          <ixy>0</ixy>
          <ixz>0</ixz>
          <iyy>0.33</iyy>
          <iyz>0</iyz>
          <izz>1</izz>
        </inertia>
      </inertial>
      <collision name="lower_link_collision">
        <pose>0 0 -1 0 0 0</pose>
        <geometry>
          <cylinder>
            <length>2.1</length>
            <radius>0.05</radius>
          </cylinder>
        </geometry>
        <drake:proximity_properties>
          <drake:dissipation_timescale>0.05</drake:dissipation_timescale>
          <drake:compliant_hydroelastic/>
          <drake:mesh_resolution_hint>0.05</drake:mesh_resolution_hint>
          <drake:hydroelastic_modulus>5e7</drake:hydroelastic_modulus>
        </drake:proximity_properties>
      </collision>
      <visual name="lower_link_visual">
        <pose>0 0 -1 0 0 0</pose>
        <geometry>
          <cylinder>
            <length>2.1</length>
            <radius>0.05</radius>
          </cylinder>
        </geometry>
      </visual>
    </link>
    <joint name="elbow" type="revolute">
      <child>lower_link</child>
      <parent>upper_link</parent>
      <axis>
        <xyz expressed_in="__model__">0 1 0</xyz>
        <limit>
        </limit>
        <dynamics>
          <damping>0.1</damping>
          <friction>0</friction>
          <spring_reference>0</spring_reference>
          <spring_stiffness>0</spring_stiffness>
        </dynamics>
      </axis>
    </joint>
    <frame name="hand">
      <pose relative_to="lower_link">0 0 -2.1 0 0 0</pose>
    </frame>
  </model>
  <model name="acrobot_two">
    <pose>0 0 2.0 0 0 0</pose>
    <link name="base_link">
      <collision name="base_link_collision">
        <geometry>
          <box>
            <size>0.2 0.2 0.2</size>
          </box>
        </geometry>
        <drake:proximity_properties>
          <drake:dissipation_timescale>0.05</drake:dissipation_timescale>
          <drake:compliant_hydroelastic/>
          <drake:mesh_resolution_hint>0.05</drake:mesh_resolution_hint>
          <drake:hydroelastic_modulus>5e7</drake:hydroelastic_modulus>
        </drake:proximity_properties>
      </collision>
      <visual name="base_link_visual">
        <geometry>
          <box>
            <size>0.2 0.2 0.2</size>
          </box>
        </geometry>
      </visual>
    </link>
    <joint name="base_weld" type="fixed">
      <child>base_link</child>
      <parent>world</parent>
    </joint>
    <link name="upper_link">
      <pose>0 0.15 0 0 0 0</pose>
      <inertial>
        <pose>0 0 -0.5 0 0 0</pose>
        <mass>1</mass>
        <inertia>
          <ixx>1</ixx>
          <ixy>0</ixy>
          <ixz>0</ixz>
          <iyy>0.083</iyy>
          <iyz>0</iyz>
          <izz>1</izz>
        </inertia>
      </inertial>
      <collision name="upper_link_collision">
        <pose>0 0 -0.5 0 0 0</pose>
        <geometry>
          <cylinder>
            <length>1.1</length>
            <radius>0.05</radius>
          </cylinder>
        </geometry>
        <drake:proximity_properties>
          <drake:dissipation_timescale>0.05</drake:dissipation_timescale>
          <drake:compliant_hydroelastic/>
          <drake:mesh_resolution_hint>0.05</drake:mesh_resolution_hint>
          <drake:hydroelastic_modulus>5e7</drake:hydroelastic_modulus>
        </drake:proximity_properties>
      </collision>
      <visual name="upper_link_visual">
        <pose>0 0 -0.5 0 0 0</pose>
        <geometry>
          <cylinder>
            <length>1.1</length>
            <radius>0.05</radius>
          </cylinder>
        </geometry>
      </visual>
    </link>
    <joint name="shoulder" type="revolute">
      <child>upper_link</child>
      <parent>base_link</parent>
      <axis>
        <xyz expressed_in="__model__">0 1 0</xyz>
        <limit>
          <effort>0</effort>
        </limit>
        <dynamics>
          <damping>0.1</damping>
          <friction>0</friction>
          <spring_reference>0</spring_reference>
          <spring_stiffness>0</spring_stiffness>
        </dynamics>
      </axis>
    </joint>
    <link name="lower_link">
      <pose>0 0.25 -1 0 0 0</pose>
      <inertial>
        <pose>0 0 -1 0 0 0</pose>
        <mass>1</mass>
        <inertia>
          <ixx>1</ixx>
          <ixy>0</ixy>
          <ixz>0</ixz>
          <iyy>0.33</iyy>
          <iyz>0</iyz>
          <izz>1</izz>
        </inertia>
      </inertial>
      <collision name="lower_link_collision">
        <pose>0 0 -1 0 0 0</pose>
        <geometry>
          <cylinder>
            <length>2.1</length>
            <radius>0.05</radius>
          </cylinder>
        </geometry>
        <drake:proximity_properties>
          <drake:dissipation_timescale>0.05</drake:dissipation_timescale>
          <drake:compliant_hydroelastic/>
          <drake:mesh_resolution_hint>0.05</drake:mesh_resolution_hint>
          <drake:hydroelastic_modulus>5e7</drake:hydroelastic_modulus>
        </drake:proximity_properties>
      </collision>
      <visual name="lower_link_visual">
        <pose>0 0 -1 0 0 0</pose>
        <geometry>
          <cylinder>
            <length>2.1</length>
            <radius>0.05</radius>
          </cylinder>
        </geometry>
      </visual>
    </link>
    <joint name="elbow" type="revolute">
      <child>lower_link</child>
      <parent>upper_link</parent>
      <axis>
        <xyz expressed_in="__model__">0 1 0</xyz>
        <limit>
        </limit>
        <dynamics>
          <damping>0.1</damping>
          <friction>0</friction>
          <spring_reference>0</spring_reference>
          <spring_stiffness>0</spring_stiffness>
        </dynamics>
      </axis>
    </joint>
    <frame name="hand">
      <pose relative_to="lower_link">0 0 -2.1 0 0 0</pose>
    </frame>
  </model>
</world>
</sdf>
