<?xml version="1.0" ?>
<!-- =================================================================================== -->
<!-- |    This document was autogenerated by xacro from valkyrie_A_sim.xacro           | -->
<!-- |    EDITING THIS FILE BY HAND IS NOT RECOMMENDED                                 | -->
<!-- =================================================================================== -->
<robot name="valkyrie" xmlns:xacro="http://ros.org/wiki/xacro">
 <link name="pelvis">
  <inertial>
   <mass value="15.470255141927101">
   </mass>
   <origin rpy="0 0 0" xyz="-0.00532 -0.003512 -0.0036">
   </origin>
   <inertia ixx="0.11866378" ixy="-0.000143482" ixz="0.003271293" iyy="0.097963425" iyz="0.002159545" izz="0.083854638">
   </inertia>
  </inertial>
  <visual>
   <geometry>
    <mesh filename="package://valkyrie/urdf/model/meshes/pelvis/pelvis.dae">
    </mesh>
   </geometry>
   <origin rpy="0.0 0.0 0.0" xyz="0.0 0.0 0.0">
   </origin>
  </visual>
  <collision>
   <geometry>
    <mesh filename="package://valkyrie/urdf/model/meshes/pelvis/pelvis.dae">
    </mesh>
   </geometry>
   <origin rpy="0 0 0" xyz="0 0 0">
   </origin>
  </collision>
 </link>
 <link name="torsoYawLink">
  <inertial>
   <mass value="0.6000393020918058">
   </mass>
   <origin rpy="0 0 0" xyz="0.000000 0.000000 -0.010000">
   </origin>
   <inertia ixx="0.000608427" ixy="-1.172e-06" ixz="1.647e-06" iyy="0.000620328" iyz="-2.33e-07" izz="0.001078108">
   </inertia>
  </inertial>
  <visual>
   <geometry>
    <mesh filename="package://valkyrie/urdf/model/meshes/torso/torsoyaw.dae">
    </mesh>
   </geometry>
   <origin rpy="0.0 0.0 0.0" xyz="0.0 0.0 0.0">
   </origin>
  </visual>
  <collision>
   <geometry>
    <mesh filename="package://valkyrie/urdf/model/meshes/torso/torsoyaw.dae">
    </mesh>
   </geometry>
   <origin rpy="0 0 0" xyz="0 0 0">
   </origin>
  </collision>
 </link>
 <link name="torsoPitchLink">
  <inertial>
   <mass value="0.14893689920528697">
   </mass>
   <origin rpy="0 0 0" xyz="0.000000 0.000000  0.005000">
   </origin>
   <inertia ixx="3.032e-05" ixy="0.0" ixz="-1.145e-06" iyy="2.1274e-05" iyz="0.0" izz="2.8285e-05">
   </inertia>
  </inertial>
  <visual>
   <geometry>
    <mesh filename="package://valkyrie/urdf/model/meshes/torso/torsopitch.dae">
    </mesh>
   </geometry>
   <origin rpy="0.0 0.0 0.0" xyz="0.0 0.0 0.0">
   </origin>
  </visual>
  <collision>
   <geometry>
    <mesh filename="package://valkyrie/urdf/model/meshes/torso/torsopitch.dae">
    </mesh>
   </geometry>
   <origin rpy="0 0 0" xyz="0 0 0">
   </origin>
  </collision>
 </link>
 <link name="torso">
  <inertial>
   <mass value="83.69402728624077">
   </mass>
   <origin rpy="0 0 0" xyz="-0.095548 -0.003337 0.243098">
   </origin>
   <inertia ixx="0.87326933" ixy="9.9563e-05" ixz="0.061345211" iyy="1.0108485" iyz="0.00181849" izz="0.77839801">
   </inertia>
  </inertial>
  <visual>
   <geometry>
    <mesh filename="package://valkyrie/urdf/model/meshes/torso/torso.dae">
    </mesh>
   </geometry>
   <origin rpy="0.0 0.0 0.0" xyz="0.0 0.0 0.0">
   </origin>
  </visual>
  <collision>
   <geometry>
    <mesh filename="package://valkyrie/urdf/model/meshes/torso/torso.dae">
    </mesh>
   </geometry>
   <origin rpy="0 0 0" xyz="0 0 0">
   </origin>
  </collision>
 </link>
 <joint name="torsoYaw" type="revolute">
  <origin rpy="0.0 0.0 0.0" xyz="0.0 0.0 0.0">
  </origin>
  <axis xyz="0 0 1">
  </axis>
  <parent link="pelvis">
  </parent>
  <child link="torsoYawLink">
  </child>
  <limit effort="190" lower="-1.329" upper="1.181" velocity="5.89">
  </limit>
  <controller_gains kd="400" kp="20000">
  </controller_gains>
  <dynamics damping="0.1" friction="0.0">
  </dynamics>
 </joint>
 <gazebo reference="torsoYaw">
  <providefeedback>
   1
  </providefeedback>
  <implicitspringdamper>
   1
  </implicitspringdamper>
 </gazebo>
 <joint name="torsoPitch" type="revolute">
  <origin rpy="0.0 0.0 0.0" xyz="0.04191 0.0 0.0">
  </origin>
  <axis xyz="0 1 0">
  </axis>
  <parent link="torsoYawLink">
  </parent>
  <child link="torsoPitchLink">
  </child>
  <limit effort="150" lower="-0.13" upper="0.666" velocity="9">
  </limit>
  <controller_gains kd="400" kp="20000">
  </controller_gains>
  <dynamics damping="0.1" friction="0.0">
  </dynamics>
 </joint>
 <gazebo reference="torsoPitch">
  <providefeedback>
   1
  </providefeedback>
  <implicitspringdamper>
   1
  </implicitspringdamper>
 </gazebo>
 <joint name="torsoRoll" type="revolute">
  <origin rpy="0.0 0.0 0.0" xyz="0.0 0.0 0.0203">
  </origin>
  <axis xyz="1 0 0">
  </axis>
  <parent link="torsoPitchLink">
  </parent>
  <child link="torso">
  </child>
  <limit effort="150" lower="-0.23" upper="0.255" velocity="9">
  </limit>
  <controller_gains kd="400" kp="20000">
  </controller_gains>
  <dynamics damping="0.1" friction="0.0">
  </dynamics>
 </joint>
 <gazebo reference="torsoRoll">
  <providefeedback>
   1
  </providefeedback>
  <implicitspringdamper>
   1
  </implicitspringdamper>
 </gazebo>
 <link name="lowerNeckPitchLink">
  <inertial>
   <mass value="2.0304679448287333">
   </mass>
   <origin rpy="0 0 0" xyz="-0.020000 0.000000  0.040000">
   </origin>
   <inertia ixx="0.001470716" ixy="-0.000126021" ixz="0.000632521" iyy="0.001851919" iyz="0.000243012" izz="0.000832117">
   </inertia>
  </inertial>
  <visual>
   <geometry>
    <mesh filename="package://valkyrie/urdf/model/meshes/head/neckj1.dae">
    </mesh>
   </geometry>
   <origin rpy="0.0 0.0 0.0" xyz="0.0 0.0 0.0">
   </origin>
  </visual>
  <collision>
   <geometry>
    <mesh filename="package://valkyrie/urdf/model/meshes/head/neckj1.dae">
    </mesh>
   </geometry>
   <origin rpy="0 0 0" xyz="0 0 0">
   </origin>
  </collision>
 </link>
 <link name="neckYawLink">
  <inertial>
   <mass value="0.7159054840865122">
   </mass>
   <origin rpy="0 0 0" xyz="-0.030000  -0.010000 0.150000">
   </origin>
   <inertia ixx="0.001997698" ixy="-0.000180062" ixz="0.000723677" iyy="0.002919928" iyz="0.000246467" izz="0.002119751">
   </inertia>
  </inertial>
  <visual>
   <geometry>
    <mesh filename="package://valkyrie/urdf/model/meshes/head/neckj2.dae">
    </mesh>
   </geometry>
   <origin rpy="0.0 0.0 0.0" xyz="0.0 0.0 0.0">
   </origin>
  </visual>
  <collision>
   <geometry>
    <mesh filename="package://valkyrie/urdf/model/meshes/head/neckj2.dae">
    </mesh>
   </geometry>
   <origin rpy="0 0 0" xyz="0 0 0">
   </origin>
  </collision>
 </link>
 <link name="upperNeckPitchLink">
  <inertial>
   <mass value="6.770452918221228">
   </mass>
   <origin rpy="0 0 0" xyz="0.100912 0.005783 0.034787">
   </origin>
   <inertia ixx="0.039847525" ixy="-0.000470418" ixz="-0.002829842" iyy="0.041418564" iyz="-0.000782564" izz="0.036841236">
   </inertia>
  </inertial>
  <visual>
   <geometry>
    <mesh filename="package://valkyrie/urdf/model/meshes/head/head_multisense_no_visor.dae">
    </mesh>
   </geometry>
   <origin rpy="0.0 0.0 0.0" xyz="0.0 0.0 0.0">
   </origin>
  </visual>
  <collision>
   <geometry>
    <mesh filename="package://valkyrie/urdf/model/meshes/head/head_multisense_no_visor.dae">
    </mesh>
   </geometry>
   <origin rpy="0 0 0" xyz="0 0 0">
   </origin>
  </collision>
 </link>
 <joint name="lowerNeckPitch" type="revolute">
  <origin rpy="0.0 0.0 0.0" xyz="0.0203518 0.0 0.33845">
  </origin>
  <axis xyz="0 1 0">
  </axis>
  <parent link="torso">
  </parent>
  <child link="lowerNeckPitchLink">
  </child>
  <limit effort="26" lower="0" upper="1.162" velocity="5">
  </limit>
  <controller_gains kd="0" kp="20000">
  </controller_gains>
  <dynamics damping="0.1" friction="0.0">
  </dynamics>
 </joint>
 <gazebo reference="lowerNeckPitch">
  <providefeedback>
   1
  </providefeedback>
  <implicitspringdamper>
   1
  </implicitspringdamper>
 </gazebo>
 <joint name="neckYaw" type="fixed">
  <origin rpy="0.0 0.0 0.0" xyz="-0.051924 0.0 0.0">
  </origin>
  <axis xyz="0 0 1">
  </axis>
  <parent link="lowerNeckPitchLink">
  </parent>
  <child link="neckYawLink">
  </child>
  <limit effort="26" lower="-1.04719755" upper="1.04719755" velocity="5">
  </limit>
  <controller_gains kd="0" kp="20000">
  </controller_gains>
  <dynamics damping="0.1" friction="0.0">
  </dynamics>
 </joint>
 <gazebo reference="neckYaw">
  <providefeedback>
   1
  </providefeedback>
  <implicitspringdamper>
   1
  </implicitspringdamper>
 </gazebo>
 <joint name="upperNeckPitch" type="fixed">
  <origin rpy="0.0 0.0 0.0" xyz="-0.06 0 0.195997">
  </origin>
  <axis xyz="0 1 0">
  </axis>
  <parent link="neckYawLink">
  </parent>
  <child link="upperNeckPitchLink">
  </child>
  <limit effort="26" lower="-0.872" upper="0.0" velocity="5">
  </limit>
  <controller_gains kd="0" kp="20000">
  </controller_gains>
  <dynamics damping="0.1" friction="0.0">
  </dynamics>
 </joint>
 <gazebo reference="upperNeckPitch">
  <providefeedback>
   1
  </providefeedback>
  <implicitspringdamper>
   1
  </implicitspringdamper>
 </gazebo>
 <link name="rightShoulderPitchLink">
  <inertial>
   <mass value="2.44945169900555">
   </mass>
   <origin rpy="0 0 0" xyz="-0.012000 -0.251 0.000000">
   </origin>
   <inertia ixx="0.013718167" ixy="0.0" ixz="0.0" iyy="0.010502833" iyz="0.0" izz="0.014806433">
   </inertia>
  </inertial>
  <visual>
   <geometry>
    <mesh filename="package://valkyrie/urdf/model/meshes/arms/aj1_right.dae">
    </mesh>
   </geometry>
   <origin rpy="0.0 0.0 0.0" xyz="0.0 0.0 0.0">
   </origin>
  </visual>
  <collision>
   <geometry>
    <mesh filename="package://valkyrie/urdf/model/meshes/arms/aj1_right.dae">
    </mesh>
   </geometry>
   <origin rpy="0 0 0" xyz="0 0 0">
   </origin>
  </collision>
 </link>
 <link name="rightShoulderRollLink">
  <inertial>
   <mass value="3.7651105791897876">
   </mass>
   <origin rpy="0 0 0" xyz="-0.008513 -0.02068 0.001088">
   </origin>
   <inertia ixx="0.009494119" ixy="-6.7294e-05" ixz="3.7177e-05" iyy="0.007680534" iyz="8.874e-06" izz="0.011454772">
   </inertia>
  </inertial>
  <visual>
   <geometry>
    <mesh filename="package://valkyrie/urdf/model/meshes/arms/aj2_right.dae">
    </mesh>
   </geometry>
   <origin rpy="0.0 0.0 0.0" xyz="0.0 0.0 0.0">
   </origin>
  </visual>
  <collision>
   <geometry>
    <mesh filename="package://valkyrie/urdf/model/meshes/arms/aj2_right.dae">
    </mesh>
   </geometry>
   <origin rpy="0 0 0" xyz="0 0 0">
   </origin>
  </collision>
 </link>
 <link name="rightShoulderYawLink">
  <inertial>
   <mass value="3.718348189239939">
   </mass>
   <origin rpy="0 0 0" xyz="-0.004304 -0.209832 -0.007295">
   </origin>
   <inertia ixx="0.039355177" ixy="0.007827077" ixz="0.000753947" iyy="0.004905765" iyz="0.002723873" izz="0.041879481">
   </inertia>
  </inertial>
  <visual>
   <geometry>
    <mesh filename="package://valkyrie/urdf/model/meshes/arms/aj3_right.dae">
    </mesh>
   </geometry>
   <origin rpy="0.0 0.0 0.0" xyz="0.0 0.0 0.0">
   </origin>
  </visual>
  <collision>
   <geometry>
    <mesh filename="package://valkyrie/urdf/model/meshes/arms/aj3_right.dae">
    </mesh>
   </geometry>
   <origin rpy="0 0 0" xyz="0 0 0">
   </origin>
  </collision>
 </link>
 <link name="rightElbowPitchLink">
  <inertial>
   <mass value="1.9617998676122035">
   </mass>
   <origin rpy="0 0 0" xyz="-0.020344 -0.014722 -0.022300">
   </origin>
   <inertia ixx="0.004285137" ixy="0.000408334" ixz="-0.003326627" iyy="0.008440601" iyz="0.000140731" izz="0.007469454">
   </inertia>
  </inertial>
  <visual>
   <geometry>
    <mesh filename="package://valkyrie/urdf/model/meshes/arms/aj4_right.dae">
    </mesh>
   </geometry>
   <origin rpy="0.0 0.0 0.0" xyz="0.0 0.0 0.0">
   </origin>
  </visual>
  <collision>
   <geometry>
    <mesh filename="package://valkyrie/urdf/model/meshes/arms/aj4_right.dae">
    </mesh>
   </geometry>
   <origin rpy="0 0 0" xyz="0 0 0">
   </origin>
  </collision>
 </link>
 <joint name="rightShoulderPitch" type="revolute">
  <origin rpy="0.0 0.0 0.0" xyz="-0.0316 0.0 0.2984">
  </origin>
  <axis xyz="0 1 0">
  </axis>
  <parent link="torso">
  </parent>
  <child link="rightShoulderPitchLink">
  </child>
  <limit effort="190" lower="-2.85" upper="2.0" velocity="5.89">
  </limit>
  <controller_gains kd="400" kp="20000">
  </controller_gains>
  <dynamics damping="0.1" friction="0.0">
  </dynamics>
 </joint>
 <gazebo reference="rightShoulderPitch">
  <providefeedback>
   1
  </providefeedback>
  <implicitspringdamper>
   1
  </implicitspringdamper>
 </gazebo>
 <joint name="rightShoulderRoll" type="revolute">
  <origin rpy="0.0 0.0 0.0" xyz="0.0 -0.2499 0.0">
  </origin>
  <axis xyz="1 0 0">
  </axis>
  <parent link="rightShoulderPitchLink">
  </parent>
  <child link="rightShoulderRollLink">
  </child>
  <limit effort="190" lower="-1.266" upper="1.519" velocity="5.89">
  </limit>
  <controller_gains kd="400" kp="20000">
  </controller_gains>
  <dynamics damping="0.1" friction="0.0">
  </dynamics>
 </joint>
 <gazebo reference="rightShoulderRoll">
  <providefeedback>
   1
  </providefeedback>
  <implicitspringdamper>
   1
  </implicitspringdamper>
 </gazebo>
 <joint name="rightShoulderYaw" type="revolute">
  <origin rpy="0.0 0.0 0.0" xyz="0.0 0.0 0.0">
  </origin>
  <axis xyz="0 1 0">
  </axis>
  <parent link="rightShoulderRollLink">
  </parent>
  <child link="rightShoulderYawLink">
  </child>
  <limit effort="65" lower="-3.1" upper="2.18" velocity="11.5">
  </limit>
  <controller_gains kd="400" kp="20000">
  </controller_gains>
  <dynamics damping="0.1" friction="0.0">
  </dynamics>
 </joint>
 <gazebo reference="rightShoulderYaw">
  <providefeedback>
   1
  </providefeedback>
  <implicitspringdamper>
   1
  </implicitspringdamper>
 </gazebo>
 <joint name="rightElbowPitch" type="revolute">
  <origin rpy="0.0 0.0 0.0" xyz="0.0254 -0.33 0.0">
  </origin>
  <axis xyz="0 0 1">
  </axis>
  <parent link="rightShoulderYawLink">
  </parent>
  <child link="rightElbowPitchLink">
  </child>
  <limit effort="65" lower="-0.12" upper="2.174" velocity="11.5">
  </limit>
  <controller_gains kd="400" kp="20000">
  </controller_gains>
  <dynamics damping="0.1" friction="0.0">
  </dynamics>
 </joint>
 <gazebo reference="rightElbowPitch">
  <providefeedback>
   1
  </providefeedback>
  <implicitspringdamper>
   1
  </implicitspringdamper>
 </gazebo>
 <link name="rightForearmLink">
  <inertial>
   <mass value="4.276390601620163">
   </mass>
   <origin rpy="0 0 0" xyz="0.015000 -0.13 0.019564">
   </origin>
   <inertia ixx="0.015011" ixy="-0.001300853" ixz="-0.000727141" iyy="0.005071567" iyz="-0.001695416" izz="0.011365657">
   </inertia>
  </inertial>
  <visual>
   <geometry>
    <mesh filename="package://valkyrie/urdf/model/meshes/arms/aj5_right.dae">
    </mesh>
   </geometry>
   <origin rpy="0.0 0.0 0.0" xyz="0.0 0.0 0.0">
   </origin>
  </visual>
  <collision>
   <geometry>
    <mesh filename="package://valkyrie/urdf/model/meshes/arms/aj5_right.dae">
    </mesh>
   </geometry>
   <origin rpy="0 0 0" xyz="0 0 0">
   </origin>
  </collision>
 </link>
 <link name="rightWristRollLink">
  <inertial>
   <mass value="0.19327264076028955">
   </mass>
   <origin rpy="0 0 0" xyz="0 -0.0 0">
   </origin>
   <inertia ixx="3.0251e-05" ixy="-1.25e-07" ixz="-3.6e-08" iyy="3.772e-05" iyz="0.0" izz="9.395e-06">
   </inertia>
  </inertial>
  <visual>
   <geometry>
    <mesh filename="package://valkyrie/urdf/model/meshes/arms/aj6_right.dae">
    </mesh>
   </geometry>
   <origin rpy="0.0 0.0 0.0" xyz="0.0 0.0 0.0">
   </origin>
  </visual>
  <collision>
   <geometry>
    <mesh filename="package://valkyrie/urdf/model/meshes/arms/aj6_right.dae">
    </mesh>
   </geometry>
   <origin rpy="0 0 0" xyz="0 0 0">
   </origin>
  </collision>
 </link>
 <link name="rightPalm">
  <inertial>
   <mass value="0.7553163058714469">
   </mass>
   <origin rpy="0 0 0" xyz="0.002954 -0.052034 -0.000236">
   </origin>
   <inertia ixx="0.000943493" ixy="3.4393e-05" ixz="-3.8828e-05" iyy="0.000711024" iyz="2.3429e-05" izz="0.000610199">
   </inertia>
  </inertial>
  <visual>
   <geometry>
    <mesh filename="package://valkyrie/urdf/model/meshes/arms/palm_right.dae">
    </mesh>
   </geometry>
   <origin rpy="0.0 0.0 0.0" xyz="0.0 0.0 0.0">
   </origin>
  </visual>
  <collision>
   <geometry>
    <mesh filename="package://valkyrie/urdf/model/meshes/arms/palm_right.dae">
    </mesh>
   </geometry>
   <origin rpy="0 0 0" xyz="0 0 0">
   </origin>
  </collision>
 </link>
 <joint name="rightForearmYaw" type="revolute">
  <origin rpy="0.0 0.0 0.0" xyz="-0.0254 0 0">
  </origin>
  <axis xyz="0 1 0">
  </axis>
  <parent link="rightElbowPitchLink">
  </parent>
  <child link="rightForearmLink">
  </child>
  <limit effort="26" lower="-2.019" upper="3.14" velocity="5">
  </limit>
  <controller_gains kd="0" kp="20000">
  </controller_gains>
  <dynamics damping="0.1" friction="0.0">
  </dynamics>
 </joint>
 <gazebo reference="rightForearmYaw">
  <providefeedback>
   1
  </providefeedback>
  <implicitspringdamper>
   1
  </implicitspringdamper>
 </gazebo>
 <joint name="rightWristRoll" type="revolute">
  <origin rpy="0.0 0.0 0.0" xyz="0.0 -0.2871 0.0">
  </origin>
  <axis xyz="1 0 0">
  </axis>
  <parent link="rightForearmLink">
  </parent>
  <child link="rightWristRollLink">
  </child>
  <limit effort="14" lower="-0.625" upper="0.62" velocity="1">
  </limit>
  <controller_gains kd="400" kp="20000">
  </controller_gains>
  <dynamics damping="0.1" friction="0.0">
  </dynamics>
 </joint>
 <gazebo reference="rightWristRoll">
  <providefeedback>
   1
  </providefeedback>
  <implicitspringdamper>
   1
  </implicitspringdamper>
 </gazebo>
 <joint name="rightWristPitch" type="revolute">
  <origin rpy="0.0 0.0 0.0" xyz="0.0 0.0 0.0">
  </origin>
  <axis xyz="0 0 1">
  </axis>
  <parent link="rightWristRollLink">
  </parent>
  <child link="rightPalm">
  </child>
  <limit effort="14" lower="-0.49" upper="0.36" velocity="1">
  </limit>
  <controller_gains kd="400" kp="20000">
  </controller_gains>
  <dynamics damping="0.1" friction="0.0">
  </dynamics>
 </joint>
 <gazebo reference="rightWristPitch">
  <providefeedback>
   1
  </providefeedback>
  <implicitspringdamper>
   1
  </implicitspringdamper>
 </gazebo>
 <link name="rightThumbRollLink">
  <inertial>
   <mass value="0.02077283747833612">
   </mass>
   <origin rpy="0 0 0" xyz="0 -0.0 0.01">
   </origin>
   <inertia ixx="2.7778767e-06" ixy="5.6718533e-09" ixz="-9.5523207e-08" iyy="3.5462642e-06" iyz="3.663718e-08" izz="1.3553297e-06">
   </inertia>
  </inertial>
  <visual>
   <geometry>
    <mesh filename="package://valkyrie/urdf/model/meshes/fingers/thumbj1_right.dae">
    </mesh>
   </geometry>
   <origin rpy="0.0 0.0 0.0" xyz="0.0 0.0 0.0">
   </origin>
  </visual>
  <collision>
   <geometry>
    <mesh filename="package://valkyrie/urdf/model/meshes/fingers/thumbj1_right.dae">
    </mesh>
   </geometry>
   <origin rpy="0 0 0" xyz="0 0 0">
   </origin>
  </collision>
 </link>
 <link name="rightThumbPitch1Link">
  <inertial>
   <mass value="0.023336743273742667">
   </mass>
   <origin rpy="0 0 0" xyz="0.0 -0.005 0.02">
   </origin>
   <inertia ixx="4.239e-06" ixy="0.0" ixz="-0.0" iyy="4.582e-06" iyz="0.0" izz="1.47e-06">
   </inertia>
  </inertial>
  <visual>
   <geometry>
    <mesh filename="package://valkyrie/urdf/model/meshes/fingers/thumbj2_right.dae">
    </mesh>
   </geometry>
   <origin rpy="0.0 0.0 0.0" xyz="0.0 0.0 0.0">
   </origin>
  </visual>
  <collision>
   <geometry>
    <mesh filename="package://valkyrie/urdf/model/meshes/fingers/thumbj2_right.dae">
    </mesh>
   </geometry>
   <origin rpy="0 0 0" xyz="0 0 0">
   </origin>
  </collision>
 </link>
 <link name="rightThumbPitch2Link">
  <inertial>
   <mass value="0.022711513975524438">
   </mass>
   <origin rpy="0 0 0" xyz="0 -0.004 0.017">
   </origin>
   <inertia ixx="1.266e-06" ixy="0.0" ixz="-0.0" iyy="1.503e-06" iyz="-0.0" izz="6.99e-07">
   </inertia>
  </inertial>
  <visual>
   <geometry>
    <mesh filename="package://valkyrie/urdf/model/meshes/fingers/thumbj3_right.dae">
    </mesh>
   </geometry>
   <origin rpy="0.0 0.0 0.0" xyz="0.0 0.0 0.0">
   </origin>
  </visual>
  <collision>
   <geometry>
    <mesh filename="package://valkyrie/urdf/model/meshes/fingers/thumbj3_right.dae">
    </mesh>
   </geometry>
   <origin rpy="0 0 0" xyz="0 0 0">
   </origin>
  </collision>
 </link>
 <link name="rightThumbPitch3Link">
  <inertial>
   <mass value="0.005384525208702597">
   </mass>
   <origin rpy="0 0 0" xyz="0 -0.004 0.01">
   </origin>
   <inertia ixx="3.22e-07" ixy="0.0" ixz="0.0" iyy="4.06e-07" iyz="0.0" izz="2.1e-07">
   </inertia>
  </inertial>
  <visual>
   <geometry>
    <mesh filename="package://valkyrie/urdf/model/meshes/fingers/thumbj4_right.dae">
    </mesh>
   </geometry>
   <origin rpy="0.0 0.0 0.0" xyz="0.0 0.0 0.0">
   </origin>
  </visual>
  <collision>
   <geometry>
    <mesh filename="package://valkyrie/urdf/model/meshes/fingers/thumbj4_right.dae">
    </mesh>
   </geometry>
   <origin rpy="0 0 0" xyz="0 0 0">
   </origin>
  </collision>
 </link>
 <joint name="rightThumbRoll" type="fixed">
  <origin rpy="0.3491 0.0 0.0" xyz="0.0049 -0.0351 0.0228">
  </origin>
  <axis xyz="0 0 1">
  </axis>
  <parent link="rightPalm">
  </parent>
  <child link="rightThumbRollLink">
  </child>
 </joint>
 <gazebo reference="rightThumbRoll">
  <implicitspringdamper>
   1
  </implicitspringdamper>
 </gazebo>
 <joint name="rightThumbPitch1" type="fixed">
  <origin rpy="-0.3491 0.0 0.0" xyz="0.0 0.0 0.0229">
  </origin>
  <axis xyz="0 0 1">
  </axis>
  <parent link="rightThumbRollLink">
  </parent>
  <child link="rightThumbPitch1Link">
  </child>
 </joint>
 <gazebo reference="rightThumbPitch1">
  <implicitspringdamper>
   1
  </implicitspringdamper>
 </gazebo>
 <joint name="rightThumbPitch2" type="fixed">
  <origin rpy="0.0 0.0 0.0" xyz="0.0 -0.0066 0.0375">
  </origin>
  <axis xyz="0 0 1">
  </axis>
  <parent link="rightThumbPitch1Link">
  </parent>
  <child link="rightThumbPitch2Link">
  </child>
 </joint>
 <gazebo reference="rightThumbPitch2">
  <implicitspringdamper>
   1
  </implicitspringdamper>
 </gazebo>
 <joint name="rightThumbPitch3" type="fixed">
  <origin rpy="0.0 0.0 0.0" xyz="0.0 -0.0049 0.0275">
  </origin>
  <axis xyz="0 0 1">
  </axis>
  <parent link="rightThumbPitch2Link">
  </parent>
  <child link="rightThumbPitch3Link">
  </child>
 </joint>
 <gazebo reference="rightThumbPitch3">
  <implicitspringdamper>
   1
  </implicitspringdamper>
 </gazebo>
 <link name="rightIndexFingerPitch1Link">
  <inertial>
   <mass value="0.023130677016509015">
   </mass>
   <origin rpy="0 0 0" xyz="0 -0.02 0">
   </origin>
   <inertia ixx="4.232e-06" ixy="-6e-08" ixz="-8e-09" iyy="1.215e-06" iyz="-7e-09" izz="3.892e-06">
   </inertia>
  </inertial>
  <visual>
   <geometry>
    <mesh filename="package://valkyrie/urdf/model/meshes/fingers/indexj1_right.dae">
    </mesh>
   </geometry>
   <origin rpy="0.0 0.0 0.0" xyz="0.0 0.0 0.0">
   </origin>
  </visual>
  <collision>
   <geometry>
    <mesh filename="package://valkyrie/urdf/model/meshes/fingers/indexj1_right.dae">
    </mesh>
   </geometry>
   <origin rpy="0 0 0" xyz="0 0 0">
   </origin>
  </collision>
 </link>
 <link name="rightIndexFingerPitch2Link">
  <inertial>
   <mass value="0.010313138346284476">
   </mass>
   <origin rpy="0 0 0" xyz="0 -0.013 0">
   </origin>
   <inertia ixx="1.562e-06" ixy="-1.7e-08" ixz="-1.3e-08" iyy="7.22e-07" iyz="3.1e-08" izz="1.255e-06">
   </inertia>
  </inertial>
  <visual>
   <geometry>
    <mesh filename="package://valkyrie/urdf/model/meshes/fingers/indexj2_right.dae">
    </mesh>
   </geometry>
   <origin rpy="0.0 0.0 0.0" xyz="0.0 0.0 0.0">
   </origin>
  </visual>
  <collision>
   <geometry>
    <mesh filename="package://valkyrie/urdf/model/meshes/fingers/indexj2_right.dae">
    </mesh>
   </geometry>
   <origin rpy="0 0 0" xyz="0 0 0">
   </origin>
  </collision>
 </link>
 <link name="rightIndexFingerPitch3Link">
  <inertial>
   <mass value="0.001">
   </mass>
   <origin rpy="0 0 0" xyz="0 -0.01 0">
   </origin>
   <inertia ixx="6.02e-07" ixy="-2.4e-08" ixz="0.0" iyy="2.09e-07" iyz="1.7e-08" izz="5.02e-07">
   </inertia>
  </inertial>
  <visual>
   <geometry>
    <mesh filename="package://valkyrie/urdf/model/meshes/fingers/indexj3_right.dae">
    </mesh>
   </geometry>
   <origin rpy="0.0 0.0 0.0" xyz="0.0 0.0 0.0">
   </origin>
  </visual>
  <collision>
   <geometry>
    <mesh filename="package://valkyrie/urdf/model/meshes/fingers/indexj3_right.dae">
    </mesh>
   </geometry>
   <origin rpy="0 0 0" xyz="0 0 0">
   </origin>
  </collision>
 </link>
 <joint name="rightIndexFingerPitch1" type="fixed">
  <origin rpy="-0.1745 0.0 0.0" xyz="0.0022 -0.0976 0.0235">
  </origin>
  <axis xyz="0 0 1">
  </axis>
  <parent link="rightPalm">
  </parent>
  <child link="rightIndexFingerPitch1Link">
  </child>
 </joint>
 <gazebo reference="rightIndexFingerPitch1">
  <implicitspringdamper>
   1
  </implicitspringdamper>
 </gazebo>
 <joint name="rightIndexFingerPitch2" type="fixed">
  <origin rpy="0.0 0.0 0.0" xyz="0.0 -0.0381 0.0">
  </origin>
  <axis xyz="0 0 1">
  </axis>
  <parent link="rightIndexFingerPitch1Link">
  </parent>
  <child link="rightIndexFingerPitch2Link">
  </child>
 </joint>
 <gazebo reference="rightIndexFingerPitch2">
  <implicitspringdamper>
   1
  </implicitspringdamper>
 </gazebo>
 <joint name="rightIndexFingerPitch3" type="fixed">
  <origin rpy="0.0 0.0 0.0" xyz="0.0 -0.0229 0">
  </origin>
  <axis xyz="0 0 1">
  </axis>
  <parent link="rightIndexFingerPitch2Link">
  </parent>
  <child link="rightIndexFingerPitch3Link">
  </child>
 </joint>
 <gazebo reference="rightIndexFingerPitch3">
  <implicitspringdamper>
   1
  </implicitspringdamper>
 </gazebo>
 <link name="rightMiddleFingerPitch1Link">
  <inertial>
   <mass value="0.02653618595440361">
   </mass>
   <origin rpy="0 0 0" xyz="0 -0.02 0">
   </origin>
   <inertia ixx="5.148e-06" ixy="-4.2e-08" ixz="-1.1e-08" iyy="1.322e-06" iyz="-4e-09" izz="4.592e-06">
   </inertia>
  </inertial>
  <visual>
   <geometry>
    <mesh filename="package://valkyrie/urdf/model/meshes/fingers/middlej1_right.dae">
    </mesh>
   </geometry>
   <origin rpy="0.0 0.0 0.0" xyz="0.0 0.0 0.0">
   </origin>
  </visual>
  <collision>
   <geometry>
    <mesh filename="package://valkyrie/urdf/model/meshes/fingers/middlej1_right.dae">
    </mesh>
   </geometry>
   <origin rpy="0 0 0" xyz="0 0 0">
   </origin>
  </collision>
 </link>
 <link name="rightMiddleFingerPitch2Link">
  <inertial>
   <mass value="0.01575439909372728">
   </mass>
   <origin rpy="0 0 0" xyz="0 -0.013 0">
   </origin>
   <inertia ixx="1.97e-06" ixy="3.4e-08" ixz="-1.1e-08" iyy="5.54e-07" iyz="-7.8e-08" izz="2.272e-06">
   </inertia>
  </inertial>
  <visual>
   <geometry>
    <mesh filename="package://valkyrie/urdf/model/meshes/fingers/middlej2_right.dae">
    </mesh>
   </geometry>
   <origin rpy="0.0 0.0 0.0" xyz="0.0 0.0 0.0">
   </origin>
  </visual>
  <collision>
   <geometry>
    <mesh filename="package://valkyrie/urdf/model/meshes/fingers/middlej2_right.dae">
    </mesh>
   </geometry>
   <origin rpy="0 0 0" xyz="0 0 0">
   </origin>
  </collision>
 </link>
 <link name="rightMiddleFingerPitch3Link">
  <inertial>
   <mass value="0.0037735049387806743">
   </mass>
   <origin rpy="0 0 0" xyz="0 -0.01 0">
   </origin>
   <inertia ixx="3.96e-07" ixy="-9e-09" ixz="-1e-09" iyy="1.6e-07" iyz="1.6e-08" izz="3.03e-07">
   </inertia>
  </inertial>
  <visual>
   <geometry>
    <mesh filename="package://valkyrie/urdf/model/meshes/fingers/middlej3_right.dae">
    </mesh>
   </geometry>
   <origin rpy="0.0 0.0 0.0" xyz="0.0 0.0 0.0">
   </origin>
  </visual>
  <collision>
   <geometry>
    <mesh filename="package://valkyrie/urdf/model/meshes/fingers/middlej3_right.dae">
    </mesh>
   </geometry>
   <origin rpy="0 0 0" xyz="0 0 0">
   </origin>
  </collision>
 </link>
 <joint name="rightMiddleFingerPitch1" type="fixed">
  <origin rpy="0.1222 0.0 0.0" xyz="0.0022 -0.097 -0.0119">
  </origin>
  <axis xyz="0 0 1">
  </axis>
  <parent link="rightPalm">
  </parent>
  <child link="rightMiddleFingerPitch1Link">
  </child>
 </joint>
 <gazebo reference="rightMiddleFingerPitch1">
  <implicitspringdamper>
   1
  </implicitspringdamper>
 </gazebo>
 <joint name="rightMiddleFingerPitch2" type="fixed">
  <origin rpy="0.0 0.0 0.0" xyz="0.0 -0.0381 0.0">
  </origin>
  <axis xyz="0 0 1">
  </axis>
  <parent link="rightMiddleFingerPitch1Link">
  </parent>
  <child link="rightMiddleFingerPitch2Link">
  </child>
 </joint>
 <gazebo reference="rightMiddleFingerPitch2">
  <implicitspringdamper>
   1
  </implicitspringdamper>
 </gazebo>
 <joint name="rightMiddleFingerPitch3" type="fixed">
  <origin rpy="0.0 0.0 0.0" xyz="0.0 -0.0229 0.0">
  </origin>
  <axis xyz="0 0 1">
  </axis>
  <parent link="rightMiddleFingerPitch2Link">
  </parent>
  <child link="rightMiddleFingerPitch3Link">
  </child>
 </joint>
 <gazebo reference="rightMiddleFingerPitch3">
  <implicitspringdamper>
   1
  </implicitspringdamper>
 </gazebo>
 <link name="rightPinkyPitch1Link">
  <inertial>
   <mass value="0.04269754623987608">
   </mass>
   <origin rpy="0 0 0" xyz="0 -0.02 0">
   </origin>
   <inertia ixx="5.148e-06" ixy="-4.2e-08" ixz="-1.1e-08" iyy="1.322e-06" iyz="-4e-09" izz="4.592e-06">
   </inertia>
  </inertial>
  <visual>
   <geometry>
    <mesh filename="package://valkyrie/urdf/model/meshes/fingers/pinkyj1_right.dae">
    </mesh>
   </geometry>
   <origin rpy="0.0 0.0 0.0" xyz="0.0 0.0 0.0">
   </origin>
  </visual>
  <collision>
   <geometry>
    <mesh filename="package://valkyrie/urdf/model/meshes/fingers/pinkyj1_right.dae">
    </mesh>
   </geometry>
   <origin rpy="0 0 0" xyz="0 0 0">
   </origin>
  </collision>
 </link>
 <link name="rightPinkyPitch2Link">
  <inertial>
   <mass value="0.0030009887897067943">
   </mass>
   <origin rpy="0 0 0" xyz="0 -0.013 0">
   </origin>
   <inertia ixx="1.97e-06" ixy="3.4e-08" ixz="-1.1e-08" iyy="5.54e-07" iyz="-7.8e-08" izz="2.272e-06">
   </inertia>
  </inertial>
  <visual>
   <geometry>
    <mesh filename="package://valkyrie/urdf/model/meshes/fingers/pinkyj2_right.dae">
    </mesh>
   </geometry>
   <origin rpy="0.0 0.0 0.0" xyz="0.0 0.0 0.0">
   </origin>
  </visual>
  <collision>
   <geometry>
    <mesh filename="package://valkyrie/urdf/model/meshes/fingers/pinkyj2_right.dae">
    </mesh>
   </geometry>
   <origin rpy="0 0 0" xyz="0 0 0">
   </origin>
  </collision>
 </link>
 <link name="rightPinkyPitch3Link">
  <inertial>
   <mass value="0.006137275551904338">
   </mass>
   <origin rpy="0 0 0" xyz="0 -0.01 0">
   </origin>
   <inertia ixx="3.96e-07" ixy="-9e-09" ixz="-1e-09" iyy="1.6e-07" iyz="1.6e-08" izz="3.03e-07">
   </inertia>
  </inertial>
  <visual>
   <geometry>
    <mesh filename="package://valkyrie/urdf/model/meshes/fingers/pinkyj3_right.dae">
    </mesh>
   </geometry>
   <origin rpy="0.0 0.0 0.0" xyz="0.0 0.0 0.0">
   </origin>
  </visual>
  <collision>
   <geometry>
    <mesh filename="package://valkyrie/urdf/model/meshes/fingers/pinkyj3_right.dae">
    </mesh>
   </geometry>
   <origin rpy="0 0 0" xyz="0 0 0">
   </origin>
  </collision>
 </link>
 <joint name="rightPinkyPitch1" type="fixed">
  <origin rpy="0.1222 0.0 0.0" xyz="0.0022 -0.0838 -0.041">
  </origin>
  <axis xyz="0 0 1">
  </axis>
  <parent link="rightPalm">
  </parent>
  <child link="rightPinkyPitch1Link">
  </child>
 </joint>
 <gazebo reference="rightPinkyPitch1">
  <implicitspringdamper>
   1
  </implicitspringdamper>
 </gazebo>
 <joint name="rightPinkyPitch2" type="fixed">
  <origin rpy="0.0 0.0 0.0" xyz="0.0 -0.0381 0.0">
  </origin>
  <axis xyz="0 0 1">
  </axis>
  <parent link="rightPinkyPitch1Link">
  </parent>
  <child link="rightPinkyPitch2Link">
  </child>
 </joint>
 <gazebo reference="rightPinkyPitch2">
  <implicitspringdamper>
   1
  </implicitspringdamper>
 </gazebo>
 <joint name="rightPinkyPitch3" type="fixed">
  <origin rpy="0.0 0.0 0.0" xyz="0.0 -0.0229 0.0">
  </origin>
  <axis xyz="0 0 1">
  </axis>
  <parent link="rightPinkyPitch2Link">
  </parent>
  <child link="rightPinkyPitch3Link">
  </child>
 </joint>
 <gazebo reference="rightPinkyPitch3">
  <implicitspringdamper>
   1
  </implicitspringdamper>
 </gazebo>
 <link name="leftShoulderPitchLink">
  <inertial>
   <mass value="2.4019813987157703">
   </mass>
   <origin rpy="0 0 0" xyz="-0.012000 0.251 0.000000">
   </origin>
   <inertia ixx="0.013718167" ixy="0.0" ixz="0.0" iyy="0.010502833" iyz="0.0" izz="0.014806433">
   </inertia>
  </inertial>
  <visual>
   <geometry>
    <mesh filename="package://valkyrie/urdf/model/meshes/arms/aj1_left.dae">
    </mesh>
   </geometry>
   <origin rpy="0.0 0.0 0.0" xyz="0.0 0.0 0.0">
   </origin>
  </visual>
  <collision>
   <geometry>
    <mesh filename="package://valkyrie/urdf/model/meshes/arms/aj1_left.dae">
    </mesh>
   </geometry>
   <origin rpy="0 0 0" xyz="0 0 0">
   </origin>
  </collision>
 </link>
 <link name="leftShoulderRollLink">
  <inertial>
   <mass value="7.012566740501539">
   </mass>
   <origin rpy="0 0 0" xyz="-0.008513 0.02068 0.001088">
   </origin>
   <inertia ixx="0.009494119" ixy="6.7294e-05" ixz="-3.7177e-05" iyy="0.007680534" iyz="8.874e-06" izz="0.011454772">
   </inertia>
  </inertial>
  <visual>
   <geometry>
    <mesh filename="package://valkyrie/urdf/model/meshes/arms/aj2_left.dae">
    </mesh>
   </geometry>
   <origin rpy="0.0 0.0 0.0" xyz="0.0 0.0 0.0">
   </origin>
  </visual>
  <collision>
   <geometry>
    <mesh filename="package://valkyrie/urdf/model/meshes/arms/aj2_left.dae">
    </mesh>
   </geometry>
   <origin rpy="0 0 0" xyz="0 0 0">
   </origin>
  </collision>
 </link>
 <link name="leftShoulderYawLink">
  <inertial>
   <mass value="5.35148590257119">
   </mass>
   <origin rpy="0 0 0" xyz="-0.004304 0.209832 -0.007295">
   </origin>
   <inertia ixx="0.039355177" ixy="0.007827077" ixz="-0.000753947" iyy="0.004905765" iyz="-0.002723873" izz="0.041879481">
   </inertia>
  </inertial>
  <visual>
   <geometry>
    <mesh filename="package://valkyrie/urdf/model/meshes/arms/aj3_left.dae">
    </mesh>
   </geometry>
   <origin rpy="0.0 0.0 0.0" xyz="0.0 0.0 0.0">
   </origin>
  </visual>
  <collision>
   <geometry>
    <mesh filename="package://valkyrie/urdf/model/meshes/arms/aj3_left.dae">
    </mesh>
   </geometry>
   <origin rpy="0 0 0" xyz="0 0 0">
   </origin>
  </collision>
 </link>
 <link name="leftElbowPitchLink">
  <inertial>
   <mass value="1.9717768945126786">
   </mass>
   <origin rpy="0 0 0" xyz="-0.020344 0.014722 -0.022300">
   </origin>
   <inertia ixx="0.004285137" ixy="-0.000408334" ixz="0.003326627" iyy="0.008440601" iyz="0.000140731" izz="0.007469454">
   </inertia>
  </inertial>
  <visual>
   <geometry>
    <mesh filename="package://valkyrie/urdf/model/meshes/arms/aj4_left.dae">
    </mesh>
   </geometry>
   <origin rpy="0.0 0.0 0.0" xyz="0.0 0.0 0.0">
   </origin>
  </visual>
  <collision>
   <geometry>
    <mesh filename="package://valkyrie/urdf/model/meshes/arms/aj4_left.dae">
    </mesh>
   </geometry>
   <origin rpy="0 0 0" xyz="0 0 0">
   </origin>
  </collision>
 </link>
 <joint name="leftShoulderPitch" type="revolute">
  <origin rpy="0.0 0.0 0.0" xyz="-0.0316 0.0 0.2984">
  </origin>
  <axis xyz="0 1 0">
  </axis>
  <parent link="torso">
  </parent>
  <child link="leftShoulderPitchLink">
  </child>
  <limit effort="190" lower="-2.85" upper="2.0" velocity="5.89">
  </limit>
  <controller_gains kd="400" kp="20000">
  </controller_gains>
  <dynamics damping="0.1" friction="0.0">
  </dynamics>
 </joint>
 <gazebo reference="leftShoulderPitch">
  <providefeedback>
   1
  </providefeedback>
  <implicitspringdamper>
   1
  </implicitspringdamper>
 </gazebo>
 <joint name="leftShoulderRoll" type="revolute">
  <origin rpy="0.0 0.0 0.0" xyz="0.0 0.2499 0.0">
  </origin>
  <axis xyz="1 0 0">
  </axis>
  <parent link="leftShoulderPitchLink">
  </parent>
  <child link="leftShoulderRollLink">
  </child>
  <limit effort="190" lower="-1.519" upper="1.266" velocity="5.89">
  </limit>
  <controller_gains kd="400" kp="20000">
  </controller_gains>
  <dynamics damping="0.1" friction="0.0">
  </dynamics>
 </joint>
 <gazebo reference="leftShoulderRoll">
  <providefeedback>
   1
  </providefeedback>
  <implicitspringdamper>
   1
  </implicitspringdamper>
 </gazebo>
 <joint name="leftShoulderYaw" type="revolute">
  <origin rpy="0.0 0.0 0.0" xyz="0.0 0.0 0.0">
  </origin>
  <axis xyz="0 1 0">
  </axis>
  <parent link="leftShoulderRollLink">
  </parent>
  <child link="leftShoulderYawLink">
  </child>
  <limit effort="65" lower="-3.1" upper="2.18" velocity="11.5">
  </limit>
  <controller_gains kd="400" kp="20000">
  </controller_gains>
  <dynamics damping="0.1" friction="0.0">
  </dynamics>
 </joint>
 <gazebo reference="leftShoulderYaw">
  <providefeedback>
   1
  </providefeedback>
  <implicitspringdamper>
   1
  </implicitspringdamper>
 </gazebo>
 <joint name="leftElbowPitch" type="revolute">
  <origin rpy="0.0 0.0 0.0" xyz="0.0254 0.33 0.0">
  </origin>
  <axis xyz="0 0 1">
  </axis>
  <parent link="leftShoulderYawLink">
  </parent>
  <child link="leftElbowPitchLink">
  </child>
  <limit effort="65" lower="-2.174" upper="0.12" velocity="11.5">
  </limit>
  <controller_gains kd="400" kp="20000">
  </controller_gains>
  <dynamics damping="0.1" friction="0.0">
  </dynamics>
 </joint>
 <gazebo reference="leftElbowPitch">
  <providefeedback>
   1
  </providefeedback>
  <implicitspringdamper>
   1
  </implicitspringdamper>
 </gazebo>
 <link name="leftForearmLink">
  <inertial>
   <mass value="2.944165199267491">
   </mass>
   <origin rpy="0 0 0" xyz="0.015000 0.13 0.019564">
   </origin>
   <inertia ixx="0.015011" ixy="0.001300853" ixz="0.000727141" iyy="0.005071567" iyz="-0.001695416" izz="0.011365657">
   </inertia>
  </inertial>
  <visual>
   <geometry>
    <mesh filename="package://valkyrie/urdf/model/meshes/arms/aj5_left.dae">
    </mesh>
   </geometry>
   <origin rpy="0.0 0.0 0.0" xyz="0.0 0.0 0.0">
   </origin>
  </visual>
  <collision>
   <geometry>
    <mesh filename="package://valkyrie/urdf/model/meshes/arms/aj5_left.dae">
    </mesh>
   </geometry>
   <origin rpy="0 0 0" xyz="0 0 0">
   </origin>
  </collision>
 </link>
 <link name="leftWristRollLink">
  <inertial>
   <mass value="0.07785499766589211">
   </mass>
   <origin rpy="0 0 0" xyz="0 0.0 0">
   </origin>
   <inertia ixx="3.0251e-05" ixy="1.25e-07" ixz="3.6e-08" iyy="3.772e-05" iyz="0.0" izz="9.395e-06">
   </inertia>
  </inertial>
  <visual>
   <geometry>
    <mesh filename="package://valkyrie/urdf/model/meshes/arms/aj6_left.dae">
    </mesh>
   </geometry>
   <origin rpy="0.0 0.0 0.0" xyz="0.0 0.0 0.0">
   </origin>
  </visual>
  <collision>
   <geometry>
    <mesh filename="package://valkyrie/urdf/model/meshes/arms/aj6_left.dae">
    </mesh>
   </geometry>
   <origin rpy="0 0 0" xyz="0 0 0">
   </origin>
  </collision>
 </link>
 <link name="leftPalm">
  <inertial>
   <mass value="0.006836457312281996">
   </mass>
   <origin rpy="0 0 0" xyz="0.002954 0.052034 -0.000236">
   </origin>
   <inertia ixx="0.000943493" ixy="3.4393e-05" ixz="3.8828e-05" iyy="0.000711024" iyz="-2.3429e-05" izz="0.000610199">
   </inertia>
  </inertial>
  <visual>
   <geometry>
    <mesh filename="package://valkyrie/urdf/model/meshes/arms/palm_left.dae">
    </mesh>
   </geometry>
   <origin rpy="0.0 0.0 0.0" xyz="0.0 0.0 0.0">
   </origin>
  </visual>
  <collision>
   <geometry>
    <mesh filename="package://valkyrie/urdf/model/meshes/arms/palm_left.dae">
    </mesh>
   </geometry>
   <origin rpy="0 0 0" xyz="0 0 0">
   </origin>
  </collision>
 </link>
 <joint name="leftForearmYaw" type="revolute">
  <origin rpy="0.0 0.0 0.0" xyz="-0.0254 0 0">
  </origin>
  <axis xyz="0 1 0">
  </axis>
  <parent link="leftElbowPitchLink">
  </parent>
  <child link="leftForearmLink">
  </child>
  <limit effort="26" lower="-2.019" upper="3.14" velocity="5">
  </limit>
  <controller_gains kd="0" kp="20000">
  </controller_gains>
  <dynamics damping="0.1" friction="0.0">
  </dynamics>
 </joint>
 <gazebo reference="leftForearmYaw">
  <providefeedback>
   1
  </providefeedback>
  <implicitspringdamper>
   1
  </implicitspringdamper>
 </gazebo>
 <joint name="leftWristRoll" type="revolute">
  <origin rpy="0.0 0.0 0.0" xyz="0.0 0.2871 0.0">
  </origin>
  <axis xyz="1 0 0">
  </axis>
  <parent link="leftForearmLink">
  </parent>
  <child link="leftWristRollLink">
  </child>
  <limit effort="14" lower="-0.62" upper="0.625" velocity="1">
  </limit>
  <controller_gains kd="400" kp="20000">
  </controller_gains>
  <dynamics damping="0.1" friction="0.0">
  </dynamics>
 </joint>
 <gazebo reference="leftWristRoll">
  <providefeedback>
   1
  </providefeedback>
  <implicitspringdamper>
   1
  </implicitspringdamper>
 </gazebo>
 <joint name="leftWristPitch" type="revolute">
  <origin rpy="0.0 0.0 0.0" xyz="0.0 0.0 0.0">
  </origin>
  <axis xyz="0 0 1">
  </axis>
  <parent link="leftWristRollLink">
  </parent>
  <child link="leftPalm">
  </child>
  <limit effort="14" lower="-0.36" upper="0.49" velocity="1">
  </limit>
  <controller_gains kd="400" kp="20000">
  </controller_gains>
  <dynamics damping="0.1" friction="0.0">
  </dynamics>
 </joint>
 <gazebo reference="leftWristPitch">
  <providefeedback>
   1
  </providefeedback>
  <implicitspringdamper>
   1
  </implicitspringdamper>
 </gazebo>
 <link name="leftThumbRollLink">
  <inertial>
   <mass value="0.014042746730727704">
   </mass>
   <origin rpy="0 0 0" xyz="0 0.0 0.01">
   </origin>
   <inertia ixx="2.7778767e-06" ixy="5.6718533e-09" ixz="9.5523207e-08" iyy="3.5462642e-06" iyz="-3.663718e-08" izz="1.3553297e-06">
   </inertia>
  </inertial>
  <visual>
   <geometry>
    <mesh filename="package://valkyrie/urdf/model/meshes/fingers/thumbj1_left.dae">
    </mesh>
   </geometry>
   <origin rpy="0.0 0.0 0.0" xyz="0.0 0.0 0.0">
   </origin>
  </visual>
  <collision>
   <geometry>
    <mesh filename="package://valkyrie/urdf/model/meshes/fingers/thumbj1_left.dae">
    </mesh>
   </geometry>
   <origin rpy="0 0 0" xyz="0 0 0">
   </origin>
  </collision>
 </link>
 <link name="leftThumbPitch1Link">
  <inertial>
   <mass value="0.0215634896910398">
   </mass>
   <origin rpy="0 0 0" xyz="0.0 0.005 0.02">
   </origin>
   <inertia ixx="4.239e-06" ixy="0.0" ixz="0.0" iyy="4.582e-06" iyz="-0.0" izz="1.47e-06">
   </inertia>
  </inertial>
  <visual>
   <geometry>
    <mesh filename="package://valkyrie/urdf/model/meshes/fingers/thumbj2_left.dae">
    </mesh>
   </geometry>
   <origin rpy="0.0 0.0 0.0" xyz="0.0 0.0 0.0">
   </origin>
  </visual>
  <collision>
   <geometry>
    <mesh filename="package://valkyrie/urdf/model/meshes/fingers/thumbj2_left.dae">
    </mesh>
   </geometry>
   <origin rpy="0 0 0" xyz="0 0 0">
   </origin>
  </collision>
 </link>
 <link name="leftThumbPitch2Link">
  <inertial>
   <mass value="0.020996889424730186">
   </mass>
   <origin rpy="0 0 0" xyz="0 0.004 0.017">
   </origin>
   <inertia ixx="1.266e-06" ixy="0.0" ixz="0.0" iyy="1.503e-06" iyz="0.0" izz="6.99e-07">
   </inertia>
  </inertial>
  <visual>
   <geometry>
    <mesh filename="package://valkyrie/urdf/model/meshes/fingers/thumbj3_left.dae">
    </mesh>
   </geometry>
   <origin rpy="0.0 0.0 0.0" xyz="0.0 0.0 0.0">
   </origin>
  </visual>
  <collision>
   <geometry>
    <mesh filename="package://valkyrie/urdf/model/meshes/fingers/thumbj3_left.dae">
    </mesh>
   </geometry>
   <origin rpy="0 0 0" xyz="0 0 0">
   </origin>
  </collision>
 </link>
 <link name="leftThumbPitch3Link">
  <inertial>
   <mass value="0.009607139546353234">
   </mass>
   <origin rpy="0 0 0" xyz="0 0.004 0.01">
   </origin>
   <inertia ixx="3.22e-07" ixy="0.0" ixz="0.0" iyy="4.06e-07" iyz="0.0" izz="2.1e-07">
   </inertia>
  </inertial>
  <visual>
   <geometry>
    <mesh filename="package://valkyrie/urdf/model/meshes/fingers/thumbj4_left.dae">
    </mesh>
   </geometry>
   <origin rpy="0.0 0.0 0.0" xyz="0.0 0.0 0.0">
   </origin>
  </visual>
  <collision>
   <geometry>
    <mesh filename="package://valkyrie/urdf/model/meshes/fingers/thumbj4_left.dae">
    </mesh>
   </geometry>
   <origin rpy="0 0 0" xyz="0 0 0">
   </origin>
  </collision>
 </link>
 <joint name="leftThumbRoll" type="fixed">
  <origin rpy="-0.3491 0.0 0.0" xyz="0.0049 0.0351 0.0228">
  </origin>
  <axis xyz="0 0 1">
  </axis>
  <parent link="leftPalm">
  </parent>
  <child link="leftThumbRollLink">
  </child>
 </joint>
 <gazebo reference="leftThumbRoll">
  <implicitspringdamper>
   1
  </implicitspringdamper>
 </gazebo>
 <joint name="leftThumbPitch1" type="fixed">
  <origin rpy="0.3491 0.0 0.0" xyz="0.0 0.0 0.0229">
  </origin>
  <axis xyz="0 0 1">
  </axis>
  <parent link="leftThumbRollLink">
  </parent>
  <child link="leftThumbPitch1Link">
  </child>
 </joint>
 <gazebo reference="leftThumbPitch1">
  <implicitspringdamper>
   1
  </implicitspringdamper>
 </gazebo>
 <joint name="leftThumbPitch2" type="fixed">
  <origin rpy="0.0 0.0 0.0" xyz="0.0 0.0066 0.0375">
  </origin>
  <axis xyz="0 0 1">
  </axis>
  <parent link="leftThumbPitch1Link">
  </parent>
  <child link="leftThumbPitch2Link">
  </child>
 </joint>
 <gazebo reference="leftThumbPitch2">
  <implicitspringdamper>
   1
  </implicitspringdamper>
 </gazebo>
 <joint name="leftThumbPitch3" type="fixed">
  <origin rpy="0.0 0.0 0.0" xyz="0.0 0.0049 0.0275">
  </origin>
  <axis xyz="0 0 1">
  </axis>
  <parent link="leftThumbPitch2Link">
  </parent>
  <child link="leftThumbPitch3Link">
  </child>
 </joint>
 <gazebo reference="leftThumbPitch3">
  <implicitspringdamper>
   1
  </implicitspringdamper>
 </gazebo>
 <link name="leftIndexFingerPitch1Link">
  <inertial>
   <mass value="0.016126731825920476">
   </mass>
   <origin rpy="0 0 0" xyz="0 0.02 0">
   </origin>
   <inertia ixx="4.232e-06" ixy="6e-08" ixz="8e-09" iyy="1.215e-06" iyz="-7e-09" izz="3.892e-06">
   </inertia>
  </inertial>
  <visual>
   <geometry>
    <mesh filename="package://valkyrie/urdf/model/meshes/fingers/indexj1_left.dae">
    </mesh>
   </geometry>
   <origin rpy="0.0 0.0 0.0" xyz="0.0 0.0 0.0">
   </origin>
  </visual>
  <collision>
   <geometry>
    <mesh filename="package://valkyrie/urdf/model/meshes/fingers/indexj1_left.dae">
    </mesh>
   </geometry>
   <origin rpy="0 0 0" xyz="0 0 0">
   </origin>
  </collision>
 </link>
 <link name="leftIndexFingerPitch2Link">
  <inertial>
   <mass value="0.015279275244821979">
   </mass>
   <origin rpy="0 0 0" xyz="0 0.013 0">
   </origin>
   <inertia ixx="1.562e-06" ixy="1.7e-08" ixz="1.3e-08" iyy="7.22e-07" iyz="3.1e-08" izz="1.255e-06">
   </inertia>
  </inertial>
  <visual>
   <geometry>
    <mesh filename="package://valkyrie/urdf/model/meshes/fingers/indexj2_left.dae">
    </mesh>
   </geometry>
   <origin rpy="0.0 0.0 0.0" xyz="0.0 0.0 0.0">
   </origin>
  </visual>
  <collision>
   <geometry>
    <mesh filename="package://valkyrie/urdf/model/meshes/fingers/indexj2_left.dae">
    </mesh>
   </geometry>
   <origin rpy="0 0 0" xyz="0 0 0">
   </origin>
  </collision>
 </link>
 <link name="leftIndexFingerPitch3Link">
  <inertial>
   <mass value="0.0047572351746645375">
   </mass>
   <origin rpy="0 0 0" xyz="0 0.01 0">
   </origin>
   <inertia ixx="6.02e-07" ixy="2.4e-08" ixz="-0.0" iyy="2.09e-07" iyz="1.7e-08" izz="5.02e-07">
   </inertia>
  </inertial>
  <visual>
   <geometry>
    <mesh filename="package://valkyrie/urdf/model/meshes/fingers/indexj3_left.dae">
    </mesh>
   </geometry>
   <origin rpy="0.0 0.0 0.0" xyz="0.0 0.0 0.0">
   </origin>
  </visual>
  <collision>
   <geometry>
    <mesh filename="package://valkyrie/urdf/model/meshes/fingers/indexj3_left.dae">
    </mesh>
   </geometry>
   <origin rpy="0 0 0" xyz="0 0 0">
   </origin>
  </collision>
 </link>
 <joint name="leftIndexFingerPitch1" type="fixed">
  <origin rpy="0.1745 0.0 0.0" xyz="0.0022 0.0976 0.0235">
  </origin>
  <axis xyz="0 0 1">
  </axis>
  <parent link="leftPalm">
  </parent>
  <child link="leftIndexFingerPitch1Link">
  </child>
 </joint>
 <gazebo reference="leftIndexFingerPitch1">
  <implicitspringdamper>
   1
  </implicitspringdamper>
 </gazebo>
 <joint name="leftIndexFingerPitch2" type="fixed">
  <origin rpy="0.0 0.0 0.0" xyz="0.0 0.0381 0.0">
  </origin>
  <axis xyz="0 0 1">
  </axis>
  <parent link="leftIndexFingerPitch1Link">
  </parent>
  <child link="leftIndexFingerPitch2Link">
  </child>
 </joint>
 <gazebo reference="leftIndexFingerPitch2">
  <implicitspringdamper>
   1
  </implicitspringdamper>
 </gazebo>
 <joint name="leftIndexFingerPitch3" type="fixed">
  <origin rpy="0.0 0.0 0.0" xyz="0.0 0.0229 0">
  </origin>
  <axis xyz="0 0 1">
  </axis>
  <parent link="leftIndexFingerPitch2Link">
  </parent>
  <child link="leftIndexFingerPitch3Link">
  </child>
 </joint>
 <gazebo reference="leftIndexFingerPitch3">
  <implicitspringdamper>
   1
  </implicitspringdamper>
 </gazebo>
 <link name="leftMiddleFingerPitch1Link">
  <inertial>
   <mass value="0.005799820628210248">
   </mass>
   <origin rpy="0 0 0" xyz="0 0.02 0">
   </origin>
   <inertia ixx="5.148e-06" ixy="4.2e-08" ixz="1.1e-08" iyy="1.322e-06" iyz="-4e-09" izz="4.592e-06">
   </inertia>
  </inertial>
  <visual>
   <geometry>
    <mesh filename="package://valkyrie/urdf/model/meshes/fingers/middlej1_left.dae">
    </mesh>
   </geometry>
   <origin rpy="0.0 0.0 0.0" xyz="0.0 0.0 0.0">
   </origin>
  </visual>
  <collision>
   <geometry>
    <mesh filename="package://valkyrie/urdf/model/meshes/fingers/middlej1_left.dae">
    </mesh>
   </geometry>
   <origin rpy="0 0 0" xyz="0 0 0">
   </origin>
  </collision>
 </link>
 <link name="leftMiddleFingerPitch2Link">
  <inertial>
   <mass value="0.0016155139515624303">
   </mass>
   <origin rpy="0 0 0" xyz="0 0.013 0">
   </origin>
   <inertia ixx="1.97e-06" ixy="-3.4e-08" ixz="1.1e-08" iyy="5.54e-07" iyz="-7.8e-08" izz="2.272e-06">
   </inertia>
  </inertial>
  <visual>
   <geometry>
    <mesh filename="package://valkyrie/urdf/model/meshes/fingers/middlej2_left.dae">
    </mesh>
   </geometry>
   <origin rpy="0.0 0.0 0.0" xyz="0.0 0.0 0.0">
   </origin>
  </visual>
  <collision>
   <geometry>
    <mesh filename="package://valkyrie/urdf/model/meshes/fingers/middlej2_left.dae">
    </mesh>
   </geometry>
   <origin rpy="0 0 0" xyz="0 0 0">
   </origin>
  </collision>
 </link>
 <link name="leftMiddleFingerPitch3Link">
  <inertial>
   <mass value="0.011852326185695369">
   </mass>
   <origin rpy="0 0 0" xyz="0 0.01 0">
   </origin>
   <inertia ixx="3.96e-07" ixy="9e-09" ixz="1e-09" iyy="1.6e-07" iyz="1.6e-08" izz="3.03e-07">
   </inertia>
  </inertial>
  <visual>
   <geometry>
    <mesh filename="package://valkyrie/urdf/model/meshes/fingers/middlej3_left.dae">
    </mesh>
   </geometry>
   <origin rpy="0.0 0.0 0.0" xyz="0.0 0.0 0.0">
   </origin>
  </visual>
  <collision>
   <geometry>
    <mesh filename="package://valkyrie/urdf/model/meshes/fingers/middlej3_left.dae">
    </mesh>
   </geometry>
   <origin rpy="0 0 0" xyz="0 0 0">
   </origin>
  </collision>
 </link>
 <joint name="leftMiddleFingerPitch1" type="fixed">
  <origin rpy="-0.1222 0.0 0.0" xyz="0.0022 0.097 -0.0119">
  </origin>
  <axis xyz="0 0 1">
  </axis>
  <parent link="leftPalm">
  </parent>
  <child link="leftMiddleFingerPitch1Link">
  </child>
 </joint>
 <gazebo reference="leftMiddleFingerPitch1">
  <implicitspringdamper>
   1
  </implicitspringdamper>
 </gazebo>
 <joint name="leftMiddleFingerPitch2" type="fixed">
  <origin rpy="0.0 0.0 0.0" xyz="0.0 0.0381 0.0">
  </origin>
  <axis xyz="0 0 1">
  </axis>
  <parent link="leftMiddleFingerPitch1Link">
  </parent>
  <child link="leftMiddleFingerPitch2Link">
  </child>
 </joint>
 <gazebo reference="leftMiddleFingerPitch2">
  <implicitspringdamper>
   1
  </implicitspringdamper>
 </gazebo>
 <joint name="leftMiddleFingerPitch3" type="fixed">
  <origin rpy="0.0 0.0 0.0" xyz="0.0 0.0229 0.0">
  </origin>
  <axis xyz="0 0 1">
  </axis>
  <parent link="leftMiddleFingerPitch2Link">
  </parent>
  <child link="leftMiddleFingerPitch3Link">
  </child>
 </joint>
 <gazebo reference="leftMiddleFingerPitch3">
  <implicitspringdamper>
   1
  </implicitspringdamper>
 </gazebo>
 <link name="leftPinkyPitch1Link">
  <inertial>
   <mass value="0.014903478182483465">
   </mass>
   <origin rpy="0 0 0" xyz="0 0.02 0">
   </origin>
   <inertia ixx="5.148e-06" ixy="4.2e-08" ixz="1.1e-08" iyy="1.322e-06" iyz="-4e-09" izz="4.592e-06">
   </inertia>
  </inertial>
  <visual>
   <geometry>
    <mesh filename="package://valkyrie/urdf/model/meshes/fingers/pinkyj1_left.dae">
    </mesh>
   </geometry>
   <origin rpy="0.0 0.0 0.0" xyz="0.0 0.0 0.0">
   </origin>
  </visual>
  <collision>
   <geometry>
    <mesh filename="package://valkyrie/urdf/model/meshes/fingers/pinkyj1_left.dae">
    </mesh>
   </geometry>
   <origin rpy="0 0 0" xyz="0 0 0">
   </origin>
  </collision>
 </link>
 <link name="leftPinkyPitch2Link">
  <inertial>
   <mass value="0.008590591341138475">
   </mass>
   <origin rpy="0 0 0" xyz="0 0.013 0">
   </origin>
   <inertia ixx="1.97e-06" ixy="-3.4e-08" ixz="1.1e-08" iyy="5.54e-07" iyz="-7.8e-08" izz="2.272e-06">
   </inertia>
  </inertial>
  <visual>
   <geometry>
    <mesh filename="package://valkyrie/urdf/model/meshes/fingers/pinkyj2_left.dae">
    </mesh>
   </geometry>
   <origin rpy="0.0 0.0 0.0" xyz="0.0 0.0 0.0">
   </origin>
  </visual>
  <collision>
   <geometry>
    <mesh filename="package://valkyrie/urdf/model/meshes/fingers/pinkyj2_left.dae">
    </mesh>
   </geometry>
   <origin rpy="0 0 0" xyz="0 0 0">
   </origin>
  </collision>
 </link>
 <link name="leftPinkyPitch3Link">
  <inertial>
   <mass value="0.0022416139198502215">
   </mass>
   <origin rpy="0 0 0" xyz="0 0.01 0">
   </origin>
   <inertia ixx="3.96e-07" ixy="9e-09" ixz="1e-09" iyy="1.6e-07" iyz="1.6e-08" izz="3.03e-07">
   </inertia>
  </inertial>
  <visual>
   <geometry>
    <mesh filename="package://valkyrie/urdf/model/meshes/fingers/pinkyj3_left.dae">
    </mesh>
   </geometry>
   <origin rpy="0.0 0.0 0.0" xyz="0.0 0.0 0.0">
   </origin>
  </visual>
  <collision>
   <geometry>
    <mesh filename="package://valkyrie/urdf/model/meshes/fingers/pinkyj3_left.dae">
    </mesh>
   </geometry>
   <origin rpy="0 0 0" xyz="0 0 0">
   </origin>
  </collision>
 </link>
 <joint name="leftPinkyPitch1" type="fixed">
  <origin rpy="-0.1222 0.0 0.0" xyz="0.0022 0.0838 -0.041">
  </origin>
  <axis xyz="0 0 1">
  </axis>
  <parent link="leftPalm">
  </parent>
  <child link="leftPinkyPitch1Link">
  </child>
 </joint>
 <gazebo reference="leftPinkyPitch1">
  <implicitspringdamper>
   1
  </implicitspringdamper>
 </gazebo>
 <joint name="leftPinkyPitch2" type="fixed">
  <origin rpy="0.0 0.0 0.0" xyz="0.0 0.0381 0.0">
  </origin>
  <axis xyz="0 0 1">
  </axis>
  <parent link="leftPinkyPitch1Link">
  </parent>
  <child link="leftPinkyPitch2Link">
  </child>
 </joint>
 <gazebo reference="leftPinkyPitch2">
  <implicitspringdamper>
   1
  </implicitspringdamper>
 </gazebo>
 <joint name="leftPinkyPitch3" type="fixed">
  <origin rpy="0.0 0.0 0.0" xyz="0.0 0.0229 0.0">
  </origin>
  <axis xyz="0 0 1">
  </axis>
  <parent link="leftPinkyPitch2Link">
  </parent>
  <child link="leftPinkyPitch3Link">
  </child>
 </joint>
 <gazebo reference="leftPinkyPitch3">
  <implicitspringdamper>
   1
  </implicitspringdamper>
 </gazebo>
 <link name="rightHipYawLink">
  <inertial>
   <mass value="3.3191009752191327">
   </mass>
   <origin rpy="0 0 0" xyz="0.02176 0.00131 0.03867">
   </origin>
   <inertia ixx="0.017260978" ixy="0.0" ixz="0.0" iyy="0.014866198" iyz="0.0" izz="0.011238178">
   </inertia>
  </inertial>
  <visual>
   <geometry>
    <mesh filename="package://valkyrie/urdf/model/meshes/legs/lj1_right.dae">
    </mesh>
   </geometry>
   <origin rpy="0.0 0.0 0.0" xyz="0.0 0.0 0.0">
   </origin>
  </visual>
  <collision>
   <geometry>
    <mesh filename="package://valkyrie/urdf/model/meshes/legs/lj1_right.dae">
    </mesh>
   </geometry>
   <origin rpy="0 0 0" xyz="0 0 0">
   </origin>
  </collision>
 </link>
 <link name="rightHipRollLink">
  <inertial>
   <mass value="0.7075321943500539">
   </mass>
   <origin rpy="0 0 0" xyz="0.012959 -0.00755 -0.015950">
   </origin>
   <inertia ixx="0.005978962" ixy="0.000234823" ixz="0.000553962" iyy="0.009372646" iyz="-0.000778956" izz="0.008193117">
   </inertia>
  </inertial>
  <visual>
   <geometry>
    <mesh filename="package://valkyrie/urdf/model/meshes/legs/lj2_right.dae">
    </mesh>
   </geometry>
   <origin rpy="0.0 0.0 0.0" xyz="0.0 0.0 0.0">
   </origin>
  </visual>
  <collision>
   <geometry>
    <mesh filename="package://valkyrie/urdf/model/meshes/legs/lj2_right.dae">
    </mesh>
   </geometry>
   <origin rpy="0 0 0" xyz="0 0 0">
   </origin>
  </collision>
 </link>
 <link name="rightHipPitchLink">
  <inertial>
   <mass value="9.115024570908759">
   </mass>
   <origin rpy="0 0 0" xyz="0.016691 -0.091397 -0.207875">
   </origin>
   <inertia ixx="0.24083413" ixy="-3.5915e-05" ixz="0.003699383" iyy="0.25689705" iyz="0.001333005" izz="0.023276352">
   </inertia>
  </inertial>
  <visual>
   <geometry>
    <mesh filename="package://valkyrie/urdf/model/meshes/legs/lj3_right.dae">
    </mesh>
   </geometry>
   <origin rpy="0.0 0.0 0.0" xyz="0.0 0.0 0.0">
   </origin>
  </visual>
  <collision>
   <geometry>
    <mesh filename="package://valkyrie/urdf/model/meshes/legs/lj3_right.dae">
    </mesh>
   </geometry>
   <origin rpy="0 0 0" xyz="0 0 0">
   </origin>
  </collision>
 </link>
 <link name="rightKneePitchLink">
  <inertial>
   <mass value="3.64496034806087">
   </mass>
   <origin rpy="0 0 0" xyz="0.002425 -0.001543 -0.189511">
   </origin>
   <inertia ixx="0.096117529" ixy="0.000107885" ixz="0.006319047" iyy="0.097118447" iyz="-0.000494739" izz="0.013722874">
   </inertia>
  </inertial>
  <visual>
   <geometry>
    <mesh filename="package://valkyrie/urdf/model/meshes/legs/lj4_right.dae">
    </mesh>
   </geometry>
   <origin rpy="0.0 0.0 0.0" xyz="0.0 0.0 0.0">
   </origin>
  </visual>
  <collision>
   <geometry>
    <mesh filename="package://valkyrie/urdf/model/meshes/legs/lj4_right.dae">
    </mesh>
   </geometry>
   <origin rpy="0 0 0" xyz="0 0 0">
   </origin>
  </collision>
 </link>
 <link name="rightAnklePitchLink">
  <inertial>
   <mass value="0.07160707493577786">
   </mass>
   <origin rpy="0 0 0" xyz="0.0 0.0 0.0">
   </origin>
   <inertia ixx="1.1226e-05" ixy="0.0" ixz="2.735e-06" iyy="2.67e-05" iyz="0.0" izz="1.8792e-05">
   </inertia>
  </inertial>
  <visual>
   <geometry>
    <mesh filename="package://valkyrie/urdf/model/meshes/legs/lj5.dae">
    </mesh>
   </geometry>
   <origin rpy="0.0 0.0 0.0" xyz="0.0 0.0 0.0">
   </origin>
  </visual>
  <collision>
   <geometry>
    <mesh filename="package://valkyrie/urdf/model/meshes/legs/lj5.dae">
    </mesh>
   </geometry>
   <origin rpy="0 0 0" xyz="0 0 0">
   </origin>
  </collision>
 </link>
 <link name="rightFoot">
  <inertial>
   <mass value="2.423664638606659">
   </mass>
   <origin rpy="0 0 0" xyz="0.037702 0.005161 -0.047634">
   </origin>
   <inertia ixx="0.008966273" ixy="-8.6029e-05" ixz="0.003944774" iyy="0.023943858" iyz="0.000105218" izz="0.028128777">
   </inertia>
  </inertial>
  <visual>
   <geometry>
    <mesh filename="package://valkyrie/urdf/model/meshes/legs/foot.dae">
    </mesh>
   </geometry>
   <origin rpy="0 0 0" xyz="0 0 0">
   </origin>
  </visual>
  <collision>
   <geometry>
    <box size="0.27 0.16 0.064">
    </box>
   </geometry>
   <origin rpy="0.0 0.0 0.0" xyz="0.066 0.0 -0.056">
   </origin>
  </collision>
  <collision group="midfoot_rear">
   <origin rpy="0 0 0" xyz="0.032 0.055 -0.09">
   </origin>
   <geometry>
    <sphere radius="0.0">
    </sphere>
   </geometry>
  </collision>
  <visual group="midfoot_rear">
   <origin rpy="0 0 0" xyz="0.032 0.055 -0.09">
   </origin>
   <geometry>
    <sphere radius="0.01">
    </sphere>
   </geometry>
  </visual>
  <collision group="midfoot_rear">
   <origin rpy="0 0 0" xyz="0.032 -0.055 -0.09">
   </origin>
   <geometry>
    <sphere radius="0.0">
    </sphere>
   </geometry>
  </collision>
  <visual group="midfoot_rear">
   <origin rpy="0 0 0" xyz="0.032 -0.055 -0.09">
   </origin>
   <geometry>
    <sphere radius="0.01">
    </sphere>
   </geometry>
  </visual>
  <collision group="midfoot_front">
   <origin rpy="0 0 0" xyz="0.102 0.055 -0.09">
   </origin>
   <geometry>
    <sphere radius="0.0">
    </sphere>
   </geometry>
  </collision>
  <visual group="midfoot_front">
   <origin rpy="0 0 0" xyz="0.102 0.055 -0.09">
   </origin>
   <geometry>
    <sphere radius="0.01">
    </sphere>
   </geometry>
  </visual>
  <collision group="midfoot_front">
   <origin rpy="0 0 0" xyz="0.102 -0.055 -0.09">
   </origin>
   <geometry>
    <sphere radius="0.0">
    </sphere>
   </geometry>
  </collision>
  <visual group="midfoot_front">
   <origin rpy="0 0 0" xyz="0.102 -0.055 -0.09">
   </origin>
   <geometry>
    <sphere radius="0.01">
    </sphere>
   </geometry>
  </visual>
  <collision group="heel">
   <origin rpy="0 0 0" xyz="-0.038 0.055 -0.09">
   </origin>
   <geometry>
    <sphere radius="0.0">
    </sphere>
   </geometry>
  </collision>
  <visual group="heel">
   <origin rpy="0 0 0" xyz="-0.038 0.055 -0.09">
   </origin>
   <geometry>
    <sphere radius="0.01">
    </sphere>
   </geometry>
  </visual>
  <collision group="heel">
   <origin rpy="0 0 0" xyz="-0.038 -0.055 -0.09">
   </origin>
   <geometry>
    <sphere radius="0.0">
    </sphere>
   </geometry>
  </collision>
  <visual group="heel">
   <origin rpy="0 0 0" xyz="-0.038 -0.055 -0.09">
   </origin>
   <geometry>
    <sphere radius="0.01">
    </sphere>
   </geometry>
  </visual>
  <collision group="toe">
   <origin rpy="0 0 0" xyz="0.172 0.055 -0.09">
   </origin>
   <geometry>
    <sphere radius="0.0">
    </sphere>
   </geometry>
  </collision>
  <visual group="toe">
   <origin rpy="0 0 0" xyz="0.172 0.055 -0.09">
   </origin>
   <geometry>
    <sphere radius="0.01">
    </sphere>
   </geometry>
  </visual>
  <collision group="toe">
   <origin rpy="0 0 0" xyz="0.172 -0.055 -0.09">
   </origin>
   <geometry>
    <sphere radius="0.0">
    </sphere>
   </geometry>
  </collision>
  <visual group="toe">
   <origin rpy="0 0 0" xyz="0.172 -0.055 -0.09">
   </origin>
   <geometry>
    <sphere radius="0.01">
    </sphere>
   </geometry>
  </visual>
 </link>
 <joint name="rightHipYaw" type="revolute">
  <origin rpy="0.0 0.0 0.0" xyz="0.0 -0.1016 -0.1853">
  </origin>
  <axis xyz="0 0 1">
  </axis>
  <parent link="pelvis">
  </parent>
  <child link="rightHipYawLink">
  </child>
  <limit effort="190" lower="-1.1" upper="0.4141" velocity="5.89">
  </limit>
  <controller_gains kd="500" kp="15000">
  </controller_gains>
  <dynamics damping="0.1" friction="0.0">
  </dynamics>
 </joint>
 <gazebo reference="rightHipYaw">
  <providefeedback>
   1
  </providefeedback>
  <implicitspringdamper>
   1
  </implicitspringdamper>
 </gazebo>
 <joint name="rightHipRoll" type="revolute">
  <origin rpy="0.0 0.0 0.0" xyz="0.0 0.0 0.0">
  </origin>
  <axis xyz="1 0 0">
  </axis>
  <parent link="rightHipYawLink">
  </parent>
  <child link="rightHipRollLink">
  </child>
  <limit effort="350" lower="-0.5515" upper="0.467" velocity="7">
  </limit>
  <controller_gains kd="500" kp="15000">
  </controller_gains>
  <dynamics damping="0.1" friction="0.0">
  </dynamics>
 </joint>
 <gazebo reference="rightHipRoll">
  <providefeedback>
   1
  </providefeedback>
  <implicitspringdamper>
   1
  </implicitspringdamper>
 </gazebo>
 <joint name="rightHipPitch" type="revolute">
  <origin rpy="0.0 0.0 0.0" xyz="0.0 0.0 -0.0609">
  </origin>
  <axis xyz="0 1 0">
  </axis>
  <parent link="rightHipRollLink">
  </parent>
  <child link="rightHipPitchLink">
  </child>
  <limit effort="350" lower="-2.42" upper="1.619" velocity="6.11">
  </limit>
  <controller_gains kd="500" kp="15000">
  </controller_gains>
  <dynamics damping="0.1" friction="0.0">
  </dynamics>
 </joint>
 <gazebo reference="rightHipPitch">
  <providefeedback>
   1
  </providefeedback>
  <implicitspringdamper>
   1
  </implicitspringdamper>
 </gazebo>
 <joint name="rightKneePitch" type="revolute">
  <origin rpy="0.0 0.0 0.0" xyz="0.000112225 -0.0361046 -0.430959">
  </origin>
  <axis xyz="0 1 0">
  </axis>
  <parent link="rightHipPitchLink">
  </parent>
  <child link="rightKneePitchLink">
  </child>
  <limit effort="350" lower="-0.083" upper="2.057" velocity="6.11">
  </limit>
  <controller_gains kd="500" kp="15000">
  </controller_gains>
  <dynamics damping="0.1" friction="0.0">
  </dynamics>
 </joint>
 <gazebo reference="rightKneePitch">
  <providefeedback>
   1
  </providefeedback>
  <implicitspringdamper>
   1
  </implicitspringdamper>
 </gazebo>
 <joint name="rightAnklePitch" type="revolute">
  <origin rpy="0.0 0.0 0.0" xyz="-0.0102381 0.0 -0.40627">
  </origin>
  <axis xyz="0 1 0">
  </axis>
  <parent link="rightKneePitchLink">
  </parent>
  <child link="rightAnklePitchLink">
  </child>
  <limit effort="205" lower="-1.8644" upper="1.875" velocity="11">
  </limit>
  <controller_gains kd="400" kp="15000">
  </controller_gains>
  <dynamics damping="0.1" friction="0.0">
  </dynamics>
 </joint>
 <gazebo reference="rightAnklePitch">
  <providefeedback>
   1
  </providefeedback>
  <implicitspringdamper>
   1
  </implicitspringdamper>
 </gazebo>
 <joint name="rightAnkleRoll" type="revolute">
  <origin rpy="0.0 0.0 0.0" xyz="0.0 0.0 0.0">
  </origin>
  <axis xyz="1 0 0">
  </axis>
  <parent link="rightAnklePitchLink">
  </parent>
  <child link="rightFoot">
  </child>
  <limit effort="205" lower="-1.349" upper="1.348" velocity="11">
  </limit>
  <controller_gains kd="400" kp="15000">
  </controller_gains>
  <dynamics damping="0.3" friction="0.0">
  </dynamics>
 </joint>
 <gazebo reference="rightAnkleRoll">
  <providefeedback>
   1
  </providefeedback>
  <implicitspringdamper>
   1
  </implicitspringdamper>
 </gazebo>
 <link name="leftHipYawLink">
  <inertial>
   <mass value="0.9791445399737175">
   </mass>
   <origin rpy="0 0 0" xyz="0.02176 -0.00131 0.03867">
   </origin>
   <inertia ixx="0.017260978" ixy="0.0" ixz="0.0" iyy="0.014866198" iyz="0.0" izz="0.011238178">
   </inertia>
  </inertial>
  <visual>
   <geometry>
    <mesh filename="package://valkyrie/urdf/model/meshes/legs/lj1_left.dae">
    </mesh>
   </geometry>
   <origin rpy="0.0 0.0 0.0" xyz="0.0 0.0 0.0">
   </origin>
  </visual>
  <collision>
   <geometry>
    <mesh filename="package://valkyrie/urdf/model/meshes/legs/lj1_left.dae">
    </mesh>
   </geometry>
   <origin rpy="0 0 0" xyz="0 0 0">
   </origin>
  </collision>
 </link>
 <link name="leftHipRollLink">
  <inertial>
   <mass value="3.613356066569415">
   </mass>
   <origin rpy="0 0 0" xyz="0.012959 0.00755 -0.015950">
   </origin>
   <inertia ixx="0.005978962" ixy="-0.000234823" ixz="0.000553962" iyy="0.009372646" iyz="0.000778956" izz="0.008193117">
   </inertia>
  </inertial>
  <visual>
   <geometry>
    <mesh filename="package://valkyrie/urdf/model/meshes/legs/lj2_left.dae">
    </mesh>
   </geometry>
   <origin rpy="0.0 0.0 0.0" xyz="0.0 0.0 0.0">
   </origin>
  </visual>
  <collision>
   <geometry>
    <mesh filename="package://valkyrie/urdf/model/meshes/legs/lj2_left.dae">
    </mesh>
   </geometry>
   <origin rpy="0 0 0" xyz="0 0 0">
   </origin>
  </collision>
 </link>
 <link name="leftHipPitchLink">
  <inertial>
   <mass value="12.384492539705128">
   </mass>
   <origin rpy="0 0 0" xyz="0.016691 0.091397 -0.207875">
   </origin>
   <inertia ixx="0.24083413" ixy="3.5915e-05" ixz="0.003699383" iyy="0.25689705" iyz="-0.001333005" izz="0.023276352">
   </inertia>
  </inertial>
  <visual>
   <geometry>
    <mesh filename="package://valkyrie/urdf/model/meshes/legs/lj3_left.dae">
    </mesh>
   </geometry>
   <origin rpy="0.0 0.0 0.0" xyz="0.0 0.0 0.0">
   </origin>
  </visual>
  <collision>
   <geometry>
    <mesh filename="package://valkyrie/urdf/model/meshes/legs/lj3_left.dae">
    </mesh>
   </geometry>
   <origin rpy="0 0 0" xyz="0 0 0">
   </origin>
  </collision>
 </link>
 <link name="leftKneePitchLink">
  <inertial>
   <mass value="6.8195068338644536">
   </mass>
   <origin rpy="0 0 0" xyz="0.002425 -0.001543 -0.189511">
   </origin>
   <inertia ixx="0.096117529" ixy="0.000107885" ixz="0.006319047" iyy="0.097118447" iyz="-0.000494739" izz="0.013722874">
   </inertia>
  </inertial>
  <visual>
   <geometry>
    <mesh filename="package://valkyrie/urdf/model/meshes/legs/lj4_left.dae">
    </mesh>
   </geometry>
   <origin rpy="0.0 0.0 0.0" xyz="0.0 0.0 0.0">
   </origin>
  </visual>
  <collision>
   <geometry>
    <mesh filename="package://valkyrie/urdf/model/meshes/legs/lj4_left.dae">
    </mesh>
   </geometry>
   <origin rpy="0 0 0" xyz="0 0 0">
   </origin>
  </collision>
 </link>
 <link name="leftAnklePitchLink">
  <inertial>
   <mass value="0.06907415693219345">
   </mass>
   <origin rpy="0 0 0" xyz="0.0 0.0 0.0">
   </origin>
   <inertia ixx="1.1226e-05" ixy="0.0" ixz="2.735e-06" iyy="2.67e-05" iyz="0.0" izz="1.8792e-05">
   </inertia>
  </inertial>
  <visual>
   <geometry>
    <mesh filename="package://valkyrie/urdf/model/meshes/legs/lj5.dae">
    </mesh>
   </geometry>
   <origin rpy="0.0 0.0 0.0" xyz="0.0 0.0 0.0">
   </origin>
  </visual>
  <collision>
   <geometry>
    <mesh filename="package://valkyrie/urdf/model/meshes/legs/lj5.dae">
    </mesh>
   </geometry>
   <origin rpy="0 0 0" xyz="0 0 0">
   </origin>
  </collision>
 </link>
 <link name="leftFoot">
  <inertial>
   <mass value="2.2226407925342317">
   </mass>
   <origin rpy="0 0 0" xyz="0.037702 0.005161 -0.047634">
   </origin>
   <inertia ixx="0.008966273" ixy="-8.6029e-05" ixz="0.003944774" iyy="0.023943858" iyz="0.000105218" izz="0.028128777">
   </inertia>
  </inertial>
  <visual>
   <geometry>
    <mesh filename="package://valkyrie/urdf/model/meshes/legs/foot.dae">
    </mesh>
   </geometry>
   <origin rpy="0 0 0" xyz="0 0 0">
   </origin>
  </visual>
  <collision>
   <geometry>
    <box size="0.27 0.16 0.064">
    </box>
   </geometry>
   <origin rpy="0.0 0.0 0.0" xyz="0.066 0.0 -0.056">
   </origin>
  </collision>
  <collision group="midfoot_rear">
   <origin rpy="0 0 0" xyz="0.032 0.055 -0.09">
   </origin>
   <geometry>
    <sphere radius="0.0">
    </sphere>
   </geometry>
  </collision>
  <visual group="midfoot_rear">
   <origin rpy="0 0 0" xyz="0.032 0.055 -0.09">
   </origin>
   <geometry>
    <sphere radius="0.01">
    </sphere>
   </geometry>
  </visual>
  <collision group="midfoot_rear">
   <origin rpy="0 0 0" xyz="0.032 -0.055 -0.09">
   </origin>
   <geometry>
    <sphere radius="0.0">
    </sphere>
   </geometry>
  </collision>
  <visual group="midfoot_rear">
   <origin rpy="0 0 0" xyz="0.032 -0.055 -0.09">
   </origin>
   <geometry>
    <sphere radius="0.01">
    </sphere>
   </geometry>
  </visual>
  <collision group="midfoot_front">
   <origin rpy="0 0 0" xyz="0.102 0.055 -0.09">
   </origin>
   <geometry>
    <sphere radius="0.0">
    </sphere>
   </geometry>
  </collision>
  <visual group="midfoot_front">
   <origin rpy="0 0 0" xyz="0.102 0.055 -0.09">
   </origin>
   <geometry>
    <sphere radius="0.01">
    </sphere>
   </geometry>
  </visual>
  <collision group="midfoot_front">
   <origin rpy="0 0 0" xyz="0.102 -0.055 -0.09">
   </origin>
   <geometry>
    <sphere radius="0.0">
    </sphere>
   </geometry>
  </collision>
  <visual group="midfoot_front">
   <origin rpy="0 0 0" xyz="0.102 -0.055 -0.09">
   </origin>
   <geometry>
    <sphere radius="0.01">
    </sphere>
   </geometry>
  </visual>
  <collision group="heel">
   <origin rpy="0 0 0" xyz="-0.038 0.055 -0.09">
   </origin>
   <geometry>
    <sphere radius="0.0">
    </sphere>
   </geometry>
  </collision>
  <visual group="heel">
   <origin rpy="0 0 0" xyz="-0.038 0.055 -0.09">
   </origin>
   <geometry>
    <sphere radius="0.01">
    </sphere>
   </geometry>
  </visual>
  <collision group="heel">
   <origin rpy="0 0 0" xyz="-0.038 -0.055 -0.09">
   </origin>
   <geometry>
    <sphere radius="0.0">
    </sphere>
   </geometry>
  </collision>
  <visual group="heel">
   <origin rpy="0 0 0" xyz="-0.038 -0.055 -0.09">
   </origin>
   <geometry>
    <sphere radius="0.01">
    </sphere>
   </geometry>
  </visual>
  <collision group="toe">
   <origin rpy="0 0 0" xyz="0.172 0.055 -0.09">
   </origin>
   <geometry>
    <sphere radius="0.0">
    </sphere>
   </geometry>
  </collision>
  <visual group="toe">
   <origin rpy="0 0 0" xyz="0.172 0.055 -0.09">
   </origin>
   <geometry>
    <sphere radius="0.01">
    </sphere>
   </geometry>
  </visual>
  <collision group="toe">
   <origin rpy="0 0 0" xyz="0.172 -0.055 -0.09">
   </origin>
   <geometry>
    <sphere radius="0.0">
    </sphere>
   </geometry>
  </collision>
  <visual group="toe">
   <origin rpy="0 0 0" xyz="0.172 -0.055 -0.09">
   </origin>
   <geometry>
    <sphere radius="0.01">
    </sphere>
   </geometry>
  </visual>
 </link>
 <joint name="leftHipYaw" type="revolute">
  <origin rpy="0.0 0.0 0.0" xyz="0.0 0.1016 -0.1853">
  </origin>
  <axis xyz="0 0 1">
  </axis>
  <parent link="pelvis">
  </parent>
  <child link="leftHipYawLink">
  </child>
  <limit effort="190" lower="-0.4141" upper="1.1" velocity="5.89">
  </limit>
  <controller_gains kd="500" kp="15000">
  </controller_gains>
  <dynamics damping="0.1" friction="0.0">
  </dynamics>
 </joint>
 <gazebo reference="leftHipYaw">
  <providefeedback>
   1
  </providefeedback>
  <implicitspringdamper>
   1
  </implicitspringdamper>
 </gazebo>
 <joint name="leftHipRoll" type="revolute">
  <origin rpy="0.0 0.0 0.0" xyz="0.0 0.0 0.0">
  </origin>
  <axis xyz="1 0 0">
  </axis>
  <parent link="leftHipYawLink">
  </parent>
  <child link="leftHipRollLink">
  </child>
  <limit effort="350" lower="-0.467" upper="0.5515" velocity="7">
  </limit>
  <controller_gains kd="500" kp="15000">
  </controller_gains>
  <dynamics damping="0.1" friction="0.0">
  </dynamics>
 </joint>
 <gazebo reference="leftHipRoll">
  <providefeedback>
   1
  </providefeedback>
  <implicitspringdamper>
   1
  </implicitspringdamper>
 </gazebo>
 <joint name="leftHipPitch" type="revolute">
  <origin rpy="0.0 0.0 0.0" xyz="0.0 0.0 -0.0609">
  </origin>
  <axis xyz="0 1 0">
  </axis>
  <parent link="leftHipRollLink">
  </parent>
  <child link="leftHipPitchLink">
  </child>
  <limit effort="350" lower="-2.42" upper="1.619" velocity="6.11">
  </limit>
  <controller_gains kd="500" kp="15000">
  </controller_gains>
  <dynamics damping="0.1" friction="0.0">
  </dynamics>
 </joint>
 <gazebo reference="leftHipPitch">
  <providefeedback>
   1
  </providefeedback>
  <implicitspringdamper>
   1
  </implicitspringdamper>
 </gazebo>
 <joint name="leftKneePitch" type="revolute">
  <origin rpy="0.0 0.0 0.0" xyz="0.000112225 0.0361046 -0.430959">
  </origin>
  <axis xyz="0 1 0">
  </axis>
  <parent link="leftHipPitchLink">
  </parent>
  <child link="leftKneePitchLink">
  </child>
  <limit effort="350" lower="-0.083" upper="2.057" velocity="6.11">
  </limit>
  <controller_gains kd="500" kp="15000">
  </controller_gains>
  <dynamics damping="0.1" friction="0.0">
  </dynamics>
 </joint>
 <gazebo reference="leftKneePitch">
  <providefeedback>
   1
  </providefeedback>
  <implicitspringdamper>
   1
  </implicitspringdamper>
 </gazebo>
 <joint name="leftAnklePitch" type="revolute">
  <origin rpy="0.0 0.0 0.0" xyz="-0.0102381 0.0 -0.40627">
  </origin>
  <axis xyz="0 1 0">
  </axis>
  <parent link="leftKneePitchLink">
  </parent>
  <child link="leftAnklePitchLink">
  </child>
  <limit effort="205" lower="-1.8644" upper="1.875" velocity="11">
  </limit>
  <controller_gains kd="400" kp="15000">
  </controller_gains>
  <dynamics damping="0.1" friction="0.0">
  </dynamics>
 </joint>
 <gazebo reference="leftAnklePitch">
  <providefeedback>
   1
  </providefeedback>
  <implicitspringdamper>
   1
  </implicitspringdamper>
 </gazebo>
 <joint name="leftAnkleRoll" type="revolute">
  <origin rpy="0.0 0.0 0.0" xyz="0.0 0.0 0.0">
  </origin>
  <axis xyz="1 0 0">
  </axis>
  <parent link="leftAnklePitchLink">
  </parent>
  <child link="leftFoot">
  </child>
  <limit effort="205" lower="-1.349" upper="1.348" velocity="11">
  </limit>
  <controller_gains kd="400" kp="15000">
  </controller_gains>
  <dynamics damping="0.3" friction="0.0">
  </dynamics>
 </joint>
 <gazebo reference="leftAnkleRoll">
  <providefeedback>
   1
  </providefeedback>
  <implicitspringdamper>
   1
  </implicitspringdamper>
 </gazebo>
 <link name="rightPelvisIMU_Frame">
  <!-- Virtual Link -->
  <inertial>
   <mass value="0.001">
   </mass>
   <origin rpy="0 0 0" xyz="0 0 0">
   </origin>
   <inertia ixx="3.33333333333e-22" ixy="0.0" ixz="0.0" iyy="3.33333333333e-22" iyz="0.0" izz="5e-22">
   </inertia>
  </inertial>
 </link>
 <joint name="rightPelvisIMU_Offset" type="fixed">
  <origin rpy="-1.57 0.0 1.274" xyz="0.0515 -0.115 -0.042">
  </origin>
  <axis xyz="0 0 1">
  </axis>
  <parent link="pelvis">
  </parent>
  <child link="rightPelvisIMU_Frame">
  </child>
 </joint>
 <gazebo reference="rightPelvisIMU_Offset">
  <implicitspringdamper>
   1
  </implicitspringdamper>
 </gazebo>
 <gazebo reference="rightPelvisIMU_Frame">
  <sensor name="rightPelvisIMU" type="imu">
   <always_on>
    true
   </always_on>
   <pose>
    0.0515 -0.115 -0.042 -1.57 0.0 1.274
   </pose>
   <imu>
    <noise>
     <type>
      gaussian
     </type>
     <rate>
      <mean>
       0
      </mean>
      <stddev>
       0.0002
      </stddev>
      <bias_mean>
       7.5e-06
      </bias_mean>
      <bias_stddev>
       8e-07
      </bias_stddev>
     </rate>
     <accel>
      <mean>
       0
      </mean>
      <stddev>
       0.017
      </stddev>
      <bias_mean>
       0.1
      </bias_mean>
      <bias_stddev>
       0.001
      </bias_stddev>
     </accel>
    </noise>
   </imu>
  </sensor>
 </gazebo>
 <link name="leftPelvisIMU_Frame">
  <!-- Virtual Link -->
  <inertial>
   <mass value="0.001">
   </mass>
   <origin rpy="0 0 0" xyz="0 0 0">
   </origin>
   <inertia ixx="3.33333333333e-22" ixy="0.0" ixz="0.0" iyy="3.33333333333e-22" iyz="0.0" izz="5e-22">
   </inertia>
  </inertial>
 </link>
 <joint name="leftPelvisIMU_Offset" type="fixed">
  <origin rpy="1.57 0 -1.274" xyz="0.0515 0.115 -0.042">
  </origin>
  <axis xyz="0 0 1">
  </axis>
  <parent link="pelvis">
  </parent>
  <child link="leftPelvisIMU_Frame">
  </child>
 </joint>
 <gazebo reference="leftPelvisIMU_Offset">
  <implicitspringdamper>
   1
  </implicitspringdamper>
 </gazebo>
 <gazebo reference="leftPelvisIMU_Frame">
  <sensor name="leftPelvisIMU" type="imu">
   <always_on>
    true
   </always_on>
   <pose>
    0.0515 0.115 -0.042 1.57 0 -1.274
   </pose>
   <imu>
    <noise>
     <type>
      gaussian
     </type>
     <rate>
      <mean>
       0
      </mean>
      <stddev>
       0.0002
      </stddev>
      <bias_mean>
       7.5e-06
      </bias_mean>
      <bias_stddev>
       8e-07
      </bias_stddev>
     </rate>
     <accel>
      <mean>
       0
      </mean>
      <stddev>
       0.017
      </stddev>
      <bias_mean>
       0.1
      </bias_mean>
      <bias_stddev>
       0.001
      </bias_stddev>
     </accel>
    </noise>
   </imu>
  </sensor>
 </gazebo>
 <link name="leftCOP_Frame">
  <inertial>
   <mass value="0.08202234192297295">
   </mass>
   <origin rpy="0 0 0" xyz="0 0 0">
   </origin>
   <inertia ixx="8.33333333333e-05" ixy="0.0" ixz="0.0" iyy="8.33333333333e-05" iyz="0.0" izz="0.000125">
   </inertia>
  </inertial>
 </link>
 <joint name="leftCOP_Offset" type="fixed">
  <origin rpy="0.0 0.13 0.0" xyz="0.0189 0.0 -0.0783">
  </origin>
  <axis xyz="0 0 1">
  </axis>
  <parent link="leftFoot">
  </parent>
  <child link="leftCOP_Frame">
  </child>
 </joint>
 <gazebo reference="leftCOP_Offset">
  <implicitspringdamper>
   1
  </implicitspringdamper>
 </gazebo>
 <link name="leftLegSixAxis_Frame">
  <!-- Virtual Link -->
  <inertial>
   <mass value="0.001">
   </mass>
   <origin rpy="0 0 0" xyz="0 0 0">
   </origin>
   <inertia ixx="3.33333333333e-22" ixy="0.0" ixz="0.0" iyy="3.33333333333e-22" iyz="0.0" izz="5e-22">
   </inertia>
  </inertial>
 </link>
 <joint name="leftLegSixAxis_Offset" type="fixed">
  <origin rpy="3.14 0.0 -1.047" xyz="0.0215646 0.0 -0.051054">
  </origin>
  <axis xyz="0 0 1">
  </axis>
  <parent link="leftFoot">
  </parent>
  <child link="leftLegSixAxis_Frame">
  </child>
 </joint>
 <gazebo reference="leftLegSixAxis_Offset">
  <implicitspringdamper>
   1
  </implicitspringdamper>
 </gazebo>
 <gazebo reference="leftLegSixAxis_Offset">
  <sensor name="leftLegSixAxis" type="force_torque">
  </sensor>
 </gazebo>
 <link name="rightCOP_Frame">
  <inertial>
   <mass value="0.013685869883416163">
   </mass>
   <origin rpy="0 0 0" xyz="0 0 0">
   </origin>
   <inertia ixx="8.33333333333e-05" ixy="0.0" ixz="0.0" iyy="8.33333333333e-05" iyz="0.0" izz="0.000125">
   </inertia>
  </inertial>
 </link>
 <joint name="rightCOP_Offset" type="fixed">
  <origin rpy="0.0 0.13 0.0" xyz="0.0189 0.0 -0.0783">
  </origin>
  <axis xyz="0 0 1">
  </axis>
  <parent link="rightFoot">
  </parent>
  <child link="rightCOP_Frame">
  </child>
 </joint>
 <gazebo reference="rightCOP_Offset">
  <implicitspringdamper>
   1
  </implicitspringdamper>
 </gazebo>
 <link name="rightLegSixAxis_Frame">
  <!-- Virtual Link -->
  <inertial>
   <mass value="0.001">
   </mass>
   <origin rpy="0 0 0" xyz="0 0 0">
   </origin>
   <inertia ixx="3.33333333333e-22" ixy="0.0" ixz="0.0" iyy="3.33333333333e-22" iyz="0.0" izz="5e-22">
   </inertia>
  </inertial>
 </link>
 <joint name="rightLegSixAxis_Offset" type="fixed">
  <origin rpy="3.14 0.0 -1.047" xyz="0.0215646 0.0 -0.051054">
  </origin>
  <axis xyz="0 0 1">
  </axis>
  <parent link="rightFoot">
  </parent>
  <child link="rightLegSixAxis_Frame">
  </child>
 </joint>
 <gazebo reference="rightLegSixAxis_Offset">
  <implicitspringdamper>
   1
  </implicitspringdamper>
 </gazebo>
 <gazebo reference="rightLegSixAxis_Offset">
  <sensor name="rightLegSixAxis" type="force_torque">
  </sensor>
 </gazebo>
 <joint name="multisense_head_root_joint" type="fixed">
  <origin rpy="-3.14159 0.130899694 0.0" xyz="0.183585961 0.0 0.075353826">
  </origin>
  <axis xyz="0 0 1">
  </axis>
  <parent link="upperNeckPitchLink">
  </parent>
  <child link="head">
  </child>
 </joint>
 <gazebo reference="multisense_head_root_joint">
  <implicitspringdamper>
   1
  </implicitspringdamper>
 </gazebo>
 <link name="rightTorsoIMU_Frame">
  <!-- Virtual Link -->
  <inertial>
   <mass value="0.001">
   </mass>
   <origin rpy="0 0 0" xyz="0 0 0">
   </origin>
   <inertia ixx="3.33333333333e-22" ixy="0.0" ixz="0.0" iyy="3.33333333333e-22" iyz="0.0" izz="5e-22">
   </inertia>
  </inertial>
 </link>
 <joint name="rightTorsoIMU_Offset" type="fixed">
  <origin rpy="-1.57 0.0 3.14" xyz="-0.047 -0.134 0.363">
  </origin>
  <axis xyz="0 0 1">
  </axis>
  <parent link="torso">
  </parent>
  <child link="rightTorsoIMU_Frame">
  </child>
 </joint>
 <gazebo reference="rightTorsoIMU_Offset">
  <implicitspringdamper>
   1
  </implicitspringdamper>
 </gazebo>
 <gazebo reference="rightTorsoIMU_Frame">
  <sensor name="rightTorsoIMU" type="imu">
   <always_on>
    true
   </always_on>
   <pose>
    -0.047 -0.134 0.363 -1.57 0.0 3.14
   </pose>
   <imu>
    <noise>
     <type>
      gaussian
     </type>
     <rate>
      <mean>
       0
      </mean>
      <stddev>
       0.0002
      </stddev>
      <bias_mean>
       7.5e-06
      </bias_mean>
      <bias_stddev>
       8e-07
      </bias_stddev>
     </rate>
     <accel>
      <mean>
       0
      </mean>
      <stddev>
       0.017
      </stddev>
      <bias_mean>
       0.1
      </bias_mean>
      <bias_stddev>
       0.001
      </bias_stddev>
     </accel>
    </noise>
   </imu>
  </sensor>
 </gazebo>
 <link name="leftTorsoIMU_Frame">
  <!-- Virtual Link -->
  <inertial>
   <mass value="0.001">
   </mass>
   <origin rpy="0 0 0" xyz="0 0 0">
   </origin>
   <inertia ixx="3.33333333333e-22" ixy="0.0" ixz="0.0" iyy="3.33333333333e-22" iyz="0.0" izz="5e-22">
   </inertia>
  </inertial>
 </link>
 <joint name="leftTorsoIMU_Offset" type="fixed">
  <origin rpy="1.57 0.0 3.14" xyz="-0.047 0.134 0.363">
  </origin>
  <axis xyz="0 0 1">
  </axis>
  <parent link="torso">
  </parent>
  <child link="leftTorsoIMU_Frame">
  </child>
 </joint>
 <gazebo reference="leftTorsoIMU_Offset">
  <implicitspringdamper>
   1
  </implicitspringdamper>
 </gazebo>
 <gazebo reference="leftTorsoIMU_Frame">
  <sensor name="leftTorsoIMU" type="imu">
   <always_on>
    true
   </always_on>
   <pose>
    -0.047 0.134 0.363 1.57 0.0 3.14
   </pose>
   <imu>
    <noise>
     <type>
      gaussian
     </type>
     <rate>
      <mean>
       0
      </mean>
      <stddev>
       0.0002
      </stddev>
      <bias_mean>
       7.5e-06
      </bias_mean>
      <bias_stddev>
       8e-07
      </bias_stddev>
     </rate>
     <accel>
      <mean>
       0
      </mean>
      <stddev>
       0.017
      </stddev>
      <bias_mean>
       0.1
      </bias_mean>
      <bias_stddev>
       0.001
      </bias_stddev>
     </accel>
    </noise>
   </imu>
  </sensor>
 </gazebo>
 <link name="rightHazardCamera_Frame">
  <!-- Virtual Link -->
  <inertial>
   <mass value="0.001">
   </mass>
   <origin rpy="0 0 0" xyz="0 0 0">
   </origin>
   <inertia ixx="3.33333333333e-22" ixy="0.0" ixz="0.0" iyy="3.33333333333e-22" iyz="0.0" izz="5e-22">
   </inertia>
  </inertial>
 </link>
 <gazebo reference="rightHazardCamera_Frame">
  <sensor name="rightHazardCamera" type="camera">
   <camera>
    <image>
     <width>
      1280
     </width>
     <height>
      1024
     </height>
     <format>
      R8G8B8
     </format>
    </image>
    <horizontal_fov>
     1.378
    </horizontal_fov>
    <clip>
     <near>
      0.1
     </near>
     <far>
      100
     </far>
    </clip>
   </camera>
   <update_rate>
    60
   </update_rate>
  </sensor>
 </gazebo>
 <joint name="rightHazardCamera_Offset" type="fixed">
  <origin rpy="1.57 0.0 1.57" xyz="0.0345 -0.0406 0.1135">
  </origin>
  <axis xyz="0 0 1">
  </axis>
  <parent link="torso">
  </parent>
  <child link="rightHazardCamera_Frame">
  </child>
 </joint>
 <gazebo reference="rightHazardCamera_Offset">
  <implicitspringdamper>
   1
  </implicitspringdamper>
 </gazebo>
 <link name="leftHazardCamera_Frame">
  <!-- Virtual Link -->
  <inertial>
   <mass value="0.001">
   </mass>
   <origin rpy="0 0 0" xyz="0 0 0">
   </origin>
   <inertia ixx="3.33333333333e-22" ixy="0.0" ixz="0.0" iyy="3.33333333333e-22" iyz="0.0" izz="5e-22">
   </inertia>
  </inertial>
 </link>
 <gazebo reference="leftHazardCamera_Frame">
  <sensor name="leftHazardCamera" type="camera">
   <camera>
    <image>
     <width>
      1280
     </width>
     <height>
      1024
     </height>
     <format>
      R8G8B8
     </format>
    </image>
    <horizontal_fov>
     1.378
    </horizontal_fov>
    <clip>
     <near>
      0.1
     </near>
     <far>
      100
     </far>
    </clip>
   </camera>
   <update_rate>
    60
   </update_rate>
  </sensor>
 </gazebo>
 <joint name="leftHazardCamera_Offset" type="fixed">
  <origin rpy="1.57 0.0 1.57" xyz="0.0345 0.0406 0.1135">
  </origin>
  <axis xyz="0 0 1">
  </axis>
  <parent link="torso">
  </parent>
  <child link="leftHazardCamera_Frame">
  </child>
 </joint>
 <gazebo reference="leftHazardCamera_Offset">
  <implicitspringdamper>
   1
  </implicitspringdamper>
 </gazebo>
 <transmission name="torsoYawTransmission">
  <type>
   transmission_interface/SimpleTransmission
  </type>
  <joint name="torsoYaw">
  </joint>
  <actuator name="torsoYaw">
   <node name="/trunk/j1">
   </node>
   <mechanicalreduction>
    1
   </mechanicalreduction>
   <api name="TurboDriverDRC_v4">
   </api>
  </actuator>
 </transmission>
 <transmission name="torsoPitchTransmission">
  <type>
   transmission_interface/SimpleTransmission
  </type>
  <joint name="torsoPitch">
  </joint>
  <actuator name="waistLeftActuator">
   <node name="/trunk/waist/left_actuator">
   </node>
   <mechanicalreduction>
    1
   </mechanicalreduction>
   <api name="TurboDriverDRC_v4">
   </api>
  </actuator>
 </transmission>
 <transmission name="torsoRollTransmission">
  <type>
   transmission_interface/SimpleTransmission
  </type>
  <joint name="torsoRoll">
  </joint>
  <actuator name="waistRightActuator">
   <node name="/trunk/waist/right_actuator">
   </node>
   <mechanicalreduction>
    1
   </mechanicalreduction>
   <api name="TurboDriverDRC_v4">
   </api>
  </actuator>
 </transmission>
 <transmission name="leftHipYawTransmission">
  <type>
   transmission_interface/SimpleTransmission
  </type>
  <joint name="leftHipYaw">
  </joint>
  <actuator name="leftHipYaw">
   <node name="/left_leg/j1">
   </node>
   <mechanicalreduction>
    1
   </mechanicalreduction>
   <api name="TurboDriverDRC_v4">
   </api>
  </actuator>
 </transmission>
 <transmission name="leftHipRollTransmission">
  <type>
   transmission_interface/SimpleTransmission
  </type>
  <joint name="leftHipRoll">
  </joint>
  <actuator name="leftHipRoll">
   <node name="/left_leg/j2">
   </node>
   <mechanicalreduction>
    1
   </mechanicalreduction>
   <api name="TurboDriverDRC_v4">
   </api>
  </actuator>
 </transmission>
 <transmission name="leftHipPitchTransmission">
  <type>
   transmission_interface/SimpleTransmission
  </type>
  <joint name="leftHipPitch">
  </joint>
  <actuator name="leftHipPitch">
   <node name="/left_leg/j3">
   </node>
   <mechanicalreduction>
    1
   </mechanicalreduction>
   <api name="TurboDriverDRC_v4">
   </api>
  </actuator>
 </transmission>
 <transmission name="leftKneePitchTransmission">
  <type>
   transmission_interface/SimpleTransmission
  </type>
  <joint name="leftKneePitch">
  </joint>
  <actuator name="leftKneePitch">
   <node name="/left_leg/j4">
   </node>
   <mechanicalreduction>
    1
   </mechanicalreduction>
   <api name="TurboDriverDRC_v4">
   </api>
  </actuator>
 </transmission>
 <transmission name="leftAnklePitchTransmission">
  <type>
   transmission_interface/SimpleTransmission
  </type>
  <joint name="leftAnklePitch">
  </joint>
  <actuator name="leftAnkleInsideActuator">
   <node name="/left_leg/ankle/left_actuator">
   </node>
   <mechanicalreduction>
    1
   </mechanicalreduction>
   <api name="TurboDriverDRC_v4">
   </api>
  </actuator>
 </transmission>
 <transmission name="leftAnkleRollTransmission">
  <type>
   transmission_interface/SimpleTransmission
  </type>
  <joint name="leftAnkleRoll">
  </joint>
  <actuator name="leftAnkleOutsideActuator">
   <node name="/left_leg/ankle/right_actuator">
   </node>
   <mechanicalreduction>
    1
   </mechanicalreduction>
   <api name="TurboDriverDRC_v4">
   </api>
  </actuator>
 </transmission>
 <transmission name="rightHipYawTransmission">
  <type>
   transmission_interface/SimpleTransmission
  </type>
  <joint name="rightHipYaw">
  </joint>
  <actuator name="rightHipYaw">
   <node name="/right_leg/j1">
   </node>
   <mechanicalreduction>
    1
   </mechanicalreduction>
   <api name="TurboDriverDRC_v4">
   </api>
  </actuator>
 </transmission>
 <transmission name="rightHipRollTransmission">
  <type>
   transmission_interface/SimpleTransmission
  </type>
  <joint name="rightHipRoll">
  </joint>
  <actuator name="rightHipRoll">
   <node name="/right_leg/j2">
   </node>
   <mechanicalreduction>
    1
   </mechanicalreduction>
   <api name="TurboDriverDRC_v4">
   </api>
  </actuator>
 </transmission>
 <transmission name="rightHipPitchTransmission">
  <type>
   transmission_interface/SimpleTransmission
  </type>
  <joint name="rightHipPitch">
  </joint>
  <actuator name="rightHipPitch">
   <node name="/right_leg/j3">
   </node>
   <mechanicalreduction>
    1
   </mechanicalreduction>
   <api name="TurboDriverDRC_v4">
   </api>
  </actuator>
 </transmission>
 <transmission name="rightKneePitchTransmission">
  <type>
   transmission_interface/SimpleTransmission
  </type>
  <joint name="rightKneePitch">
  </joint>
  <actuator name="rightKneePitch">
   <node name="/right_leg/j4">
   </node>
   <mechanicalreduction>
    1
   </mechanicalreduction>
   <api name="TurboDriverDRC_v4">
   </api>
  </actuator>
 </transmission>
 <transmission name="rightAnklePitchTransmission">
  <type>
   transmission_interface/SimpleTransmission
  </type>
  <joint name="rightAnklePitch">
  </joint>
  <actuator name="rightAnkleInsideActuator">
   <node name="/right_leg/ankle/left_actuator">
   </node>
   <mechanicalreduction>
    1
   </mechanicalreduction>
   <api name="TurboDriverDRC_v4">
   </api>
  </actuator>
 </transmission>
 <transmission name="rightAnkleRollTransmission">
  <type>
   transmission_interface/SimpleTransmission
  </type>
  <joint name="rightAnkleRoll">
  </joint>
  <actuator name="rightAnkleOutsideActuator">
   <node name="/right_leg/ankle/right_actuator">
   </node>
   <mechanicalreduction>
    1
   </mechanicalreduction>
   <api name="TurboDriverDRC_v4">
   </api>
  </actuator>
 </transmission>
 <transmission name="leftShoulderPitchTransmission">
  <type>
   transmission_interface/SimpleTransmission
  </type>
  <joint name="leftShoulderPitch">
  </joint>
  <actuator name="leftShoulderPitch">
   <node name="/left_arm/j1">
   </node>
   <mechanicalreduction>
    1
   </mechanicalreduction>
   <api name="TurboDriverDRC_v4">
   </api>
  </actuator>
 </transmission>
 <transmission name="leftShoulderRollTransmission">
  <type>
   transmission_interface/SimpleTransmission
  </type>
  <joint name="leftShoulderRoll">
  </joint>
  <actuator name="leftShoulderRoll">
   <node name="/left_arm/j2">
   </node>
   <mechanicalreduction>
    1
   </mechanicalreduction>
   <api name="TurboDriverDRC_v4">
   </api>
  </actuator>
 </transmission>
 <transmission name="leftShoulderYawTransmission">
  <type>
   transmission_interface/SimpleTransmission
  </type>
  <joint name="leftShoulderYaw">
  </joint>
  <actuator name="leftShoulderYaw">
   <node name="/left_arm/j3">
   </node>
   <mechanicalreduction>
    1
   </mechanicalreduction>
   <api name="TurboDriverDRC_v4">
   </api>
  </actuator>
 </transmission>
 <transmission name="leftElbowPitchTransmission">
  <type>
   transmission_interface/SimpleTransmission
  </type>
  <joint name="leftElbowPitch">
  </joint>
  <actuator name="leftElbowPitch">
   <node name="/left_arm/j4">
   </node>
   <mechanicalreduction>
    1
   </mechanicalreduction>
   <api name="TurboDriverDRC_v4">
   </api>
  </actuator>
 </transmission>
 <transmission name="leftForearmYawTransmission">
  <type>
   transmission_interface/SimpleTransmission
  </type>
  <joint name="leftForearmYaw">
  </joint>
  <actuator name="leftForearmYaw">
   <node name="/left_arm/j5">
   </node>
   <mechanicalreduction>
    1
   </mechanicalreduction>
   <api name="TurboDriverDRC_v4">
   </api>
  </actuator>
 </transmission>
 <transmission name="leftWristRollTransmission">
  <type>
   transmission_interface/SimpleTransmission
  </type>
  <joint name="leftWristRoll">
  </joint>
  <actuator name="leftWristTopActuator">
   <node name="/left_arm/wrist/top_actautor">
   </node>
   <mechanicalreduction>
    1
   </mechanicalreduction>
   <api name="TurboDriverDRC_v4">
   </api>
  </actuator>
 </transmission>
 <transmission name="leftWristPitchTransmission">
  <type>
   transmission_interface/SimpleTransmission
  </type>
  <joint name="leftWristPitch">
  </joint>
  <actuator name="leftWristBottomActuator">
   <node name="/left_arm/wrist/bottom_actuator">
   </node>
   <mechanicalreduction>
    1
   </mechanicalreduction>
   <api name="TurboDriverDRC_v4">
   </api>
  </actuator>
 </transmission>
 <transmission name="rightShoulderPitchTransmission">
  <type>
   transmission_interface/SimpleTransmission
  </type>
  <joint name="rightShoulderPitch">
  </joint>
  <actuator name="rightShoulderPitch">
   <node name="/right_arm/j1">
   </node>
   <mechanicalreduction>
    1
   </mechanicalreduction>
   <api name="TurboDriverDRC_v4">
   </api>
  </actuator>
 </transmission>
 <transmission name="rightShoulderRollTransmission">
  <type>
   transmission_interface/SimpleTransmission
  </type>
  <joint name="rightShoulderRoll">
  </joint>
  <actuator name="rightShoulderRoll">
   <node name="/right_arm/j2">
   </node>
   <mechanicalreduction>
    1
   </mechanicalreduction>
   <api name="TurboDriverDRC_v4">
   </api>
  </actuator>
 </transmission>
 <transmission name="rightShoulderYawTransmission">
  <type>
   transmission_interface/SimpleTransmission
  </type>
  <joint name="rightShoulderYaw">
  </joint>
  <actuator name="rightShoulderYaw">
   <node name="/right_arm/j3">
   </node>
   <mechanicalreduction>
    1
   </mechanicalreduction>
   <api name="TurboDriverDRC_v4">
   </api>
  </actuator>
 </transmission>
 <transmission name="rightElbowPitchTransmission">
  <type>
   transmission_interface/SimpleTransmission
  </type>
  <joint name="rightElbowPitch">
  </joint>
  <actuator name="rightElbowPitch">
   <node name="/right_arm/j4">
   </node>
   <mechanicalreduction>
    1
   </mechanicalreduction>
   <api name="TurboDriverDRC_v4">
   </api>
  </actuator>
 </transmission>
 <transmission name="rightForearmYawTransmission">
  <type>
   transmission_interface/SimpleTransmission
  </type>
  <joint name="rightForearmYaw">
  </joint>
  <actuator name="rightForearmYaw">
   <node name="/right_arm/j5">
   </node>
   <mechanicalreduction>
    1
   </mechanicalreduction>
   <api name="TurboDriverDRC_v4">
   </api>
  </actuator>
 </transmission>
 <transmission name="rightWristRollTransmission">
  <type>
   transmission_interface/SimpleTransmission
  </type>
  <joint name="rightWristRoll">
  </joint>
  <actuator name="rightWristTopActuator">
   <node name="/right_arm/wrist/top_actautor">
   </node>
   <mechanicalreduction>
    1
   </mechanicalreduction>
   <api name="TurboDriverDRC_v4">
   </api>
  </actuator>
 </transmission>
 <transmission name="rightWristPitchTransmission">
  <type>
   transmission_interface/SimpleTransmission
  </type>
  <joint name="rightWristPitch">
  </joint>
  <actuator name="rightWristBottomActuator">
   <node name="/right_arm/wrist/bottom_actuator">
   </node>
   <mechanicalreduction>
    1
   </mechanicalreduction>
   <api name="TurboDriverDRC_v4">
   </api>
  </actuator>
 </transmission>
 <transmission name="lowerNeckPitchTransmission">
  <type>
   transmission_interface/SimpleTransmission
  </type>
  <joint name="lowerNeckPitch">
  </joint>
  <actuator name="lowerNeckPitch">
   <node name="/neck/j1">
   </node>
   <mechanicalreduction>
    1
   </mechanicalreduction>
   <api name="TurboDriverDRC_v4">
   </api>
  </actuator>
 </transmission>
 <!--
  <transmission name="neckYawTransmission">
    <type>transmission_interface/SimpleTransmission</type>
    <joint name="neckYaw">
      </joint>
    <actuator name="neckYaw">
      <node name="/neck/j2"/>
      <mechanicalReduction>1</mechanicalReduction>
      <api name="TurboDriverDRC_v4"/>
    </actuator>
  </transmission>
-->
 <!--
  <transmission name="upperNeckPitchTransmission">
    <type>transmission_interface/SimpleTransmission</type>
    <joint name="upperNeckPitch">
      </joint>
    <actuator name="upperNeckPitch">
      <node name="/neck/j3"/>
      <mechanicalReduction>1</mechanicalReduction>
      <api name="TurboDriverDRC_v4"/>
    </actuator>
  </transmission>
-->
 <!-- Head Link Simple Collision Meshes -->
 <link name="head">
  <inertial>
   <origin rpy="0 0 0" xyz="-0.075493 3.3383E-05 0.02774">
   </origin>
   <mass value="1.456717075383595">
   </mass>
   <inertia ixx="0.0039688" ixy="-1.5797E-06" ixz="-0.00089293" iyy="0.0041178" iyz="-6.8415E-07" izz="0.0035243">
   </inertia>
  </inertial>
  <!--     <visual>
      <origin xyz="0 0 0" rpy="0 0 0" />
      <geometry>
        <mesh filename="package://valkyrie/urdf/model/meshes/multisense/head.dae" />
      </geometry>
      <material name="">
        <color rgba="0.9098 0.44314 0.031373 1" />
      </material>
    </visual> -->
  <collision>
   <origin rpy="0 0 0" xyz="-0.0503 0 -0.00195">
   </origin>
   <geometry>
    <box size="0.1311 0.12 0.0591">
    </box>
   </geometry>
  </collision>
  <collision>
   <origin rpy="0 0 0" xyz="-0.093 0 0.0868">
   </origin>
   <geometry>
    <box size="0.0468 0.12 0.1184">
    </box>
   </geometry>
  </collision>
 </link>
 <link name="hokuyo_link">
  <inertial>
   <origin rpy="0 0 0" xyz="0.032428 0.0004084 -0.0041835">
   </origin>
   <mass value="0.07867149363589185">
   </mass>
   <inertia ixx="3.7174E-05" ixy="4.9927E-08" ixz="1.1015E-05" iyy="4.2412E-05" iyz="-9.8165E-09" izz="4.167E-05">
   </inertia>
  </inertial>
  <visual>
   <!--origin xyz="0.065774 -0.001163 -0.08809" rpy="0 0 0" /-->
   <!--origin xyz="0.045 -0.001163 -0.08809" rpy="-0.314 0 0" /-->
   <origin rpy="-0.314 0 0" xyz="0.045 -0.0261018277 -0.08342369">
   </origin>
   <geometry>
    <mesh filename="package://valkyrie/urdf/model/meshes/multisense/head_camera.dae">
    </mesh>
   </geometry>
   <material name="">
    <color rgba="0.72941 0.35686 0.023529 1">
    </color>
   </material>
  </visual>
  <collision>
   <origin rpy="0 0 0" xyz="0.01885 0 -0.02119">
   </origin>
   <geometry>
    <box size="0.08 0.06 0.04238">
    </box>
   </geometry>
  </collision>
  <collision>
   <origin rpy="0 0 0" xyz="0.03 0 0.0235">
   </origin>
   <geometry>
    <cylinder length="0.047" radius="0.024425">
    </cylinder>
   </geometry>
  </collision>
 </link>
 <gazebo reference="head">
  <mu1>
   0.9
  </mu1>
  <mu2>
   0.9
  </mu2>
 </gazebo>
 <gazebo reference="hokuyo_link">
  <mu1>
   0.9
  </mu1>
  <mu2>
   0.9
  </mu2>
 </gazebo>
 <joint name="hokuyo_joint" type="fixed">
  <origin rpy="0 0 0" xyz="-0.0446 0 0.0880">
  </origin>
  <parent link="head">
  </parent>
  <child link="hokuyo_link">
  </child>
  <axis xyz="1 0 0">
  </axis>
  <dynamics damping="0.01" friction="0">
  </dynamics>
 </joint>
 <gazebo reference="hokuyo_joint">
  <implicitspringdamper>
   1
  </implicitspringdamper>
 </gazebo>
 <!-- Hokuyo Laser -->
 <joint name="head_hokuyo_joint" type="fixed">
  <axis xyz="0 1 0">
  </axis>
  <origin rpy="0 0 0" xyz="0.03 0 0.015">
  </origin>
  <parent link="hokuyo_link">
  </parent>
  <child link="head_hokuyo_frame">
  </child>
 </joint>
 <link name="head_hokuyo_frame">
  <inertial>
   <mass value="0.001">
   </mass>
   <!-- collocate with parent link and remove mass from it -->
   <origin rpy="0 0 0" xyz="0.042428 0.0004084 0.0108165">
   </origin>
   <inertia ixx="1e-6" ixy="0" ixz="0" iyy="1e-6" iyz="0" izz="1e-6">
   </inertia>
  </inertial>
 </link>
 <gazebo reference="head_hokuyo_frame">
  <sensor name="head_hokuyo_sensor" type="gpu_ray">
   <pose>
    0 0 0 0 0 0
   </pose>
   <visualize>
    false
   </visualize>
   <update_rate>
    40
   </update_rate>
   <ray>
    <scan>
     <horizontal>
      <samples>
       1081
      </samples>
      <resolution>
       1
      </resolution>
      <min_angle>
       -2.356194
      </min_angle>
      <max_angle>
       2.356194
      </max_angle>
     </horizontal>
    </scan>
    <range>
     <min>
      0.10
     </min>
     <max>
      30.0
     </max>
     <resolution>
      0.01
     </resolution>
    </range>
    <noise>
     <type>
      gaussian
     </type>
     <!-- Noise parameters based on published spec for Hokuyo laser
               achieving "+-30mm" accuracy at range < 10m.  A mean of 0.0m and
               stddev of 0.01m will put 99.7% of samples within 0.03m of the true
               reading. -->
     <mean>
      0.0
     </mean>
     <stddev>
      0.01
     </stddev>
    </noise>
   </ray>
  </sensor>
 </gazebo>
 <!-- Stereo Camera -->
 <joint name="left_camera_frame_joint" type="fixed">
  <!-- optical frame collocated with tilting DOF -->
  <origin xyz="0.0 0.035 -0.002">
  </origin>
  <parent link="head">
  </parent>
  <child link="left_camera_frame">
  </child>
 </joint>
 <link name="left_camera_frame">
  <inertial>
   <mass value="0.001">
   </mass>
   <!-- collocate with parent link and remove mass from it -->
   <origin xyz="-0.075493 0.035033383 0.02574">
   </origin>
   <inertia ixx="1e-6" ixy="0" ixz="0" iyy="1e-6" iyz="0" izz="1e-6">
   </inertia>
  </inertial>
 </link>
 <joint name="left_camera_optical_frame_joint" type="fixed">
  <origin rpy="-1.5708 0.0 -1.5708" xyz="0 0 0">
  </origin>
  <parent link="left_camera_frame">
  </parent>
  <child link="left_camera_optical_frame">
  </child>
 </joint>
 <link name="left_camera_optical_frame"/>
 <gazebo reference="left_camera_frame">
  <sensor name="stereo_camera" type="multicamera">
   <!-- see MultiSenseSLPlugin.h for available modes -->
   <update_rate>
    10.0
   </update_rate>
   <camera name="left">
    <!-- Spec sheet says 80deg X 45deg @ 1024x544pix.  Based on feedback
             from teams, we're instead doing 80deg X 80deg @ 800x800pix. -->
    <horizontal_fov>
     1.3962634
    </horizontal_fov>
    <image>
     <width>
      1024
     </width>
     <height>
      544
     </height>
     <format>
      R8G8B8
     </format>
    </image>
    <clip>
     <near>
      0.02
     </near>
     <far>
      300
     </far>
    </clip>
    <noise>
     <type>
      gaussian
     </type>
     <!-- Noise is sampled independently per pixel on each frame.
               That pixel's noise value is added to each of its color
               channels, which at that point lie in the range [0,1].
               The stddev value of 0.007 is based on experimental data
               from a camera in a Sandia hand pointed at a static scene
               in a couple of different lighting conditions.  -->
     <mean>
      0.0
     </mean>
     <stddev>
      0.007
     </stddev>
    </noise>
   </camera>
   <camera name="right">
    <pose>
     0 -0.07 0 0 0 0
    </pose>
    <!-- Spec sheet says 80deg X 45deg @ 1024x544pix. -->
    <horizontal_fov>
     1.3962634
    </horizontal_fov>
    <image>
     <width>
      1024
     </width>
     <height>
      544
     </height>
     <format>
      R8G8B8
     </format>
    </image>
    <clip>
     <near>
      0.02
     </near>
     <far>
      300
     </far>
    </clip>
    <noise>
     <type>
      gaussian
     </type>
     <!-- Noise is sampled independently per pixel on each frame.
               That pixel's noise value is added to each of its color
               channels, which at that point lie in the range [0,1].
               The stddev value of 0.007 is based on experimental data
               from a camera in a Sandia hand pointed at a static scene
               in a couple of different lighting conditions.  -->
     <mean>
      0.0
     </mean>
     <stddev>
      0.007
     </stddev>
    </noise>
   </camera>
  </sensor>
 </gazebo>
 <joint name="right_camera_frame_joint" type="fixed">
  <origin xyz="0.0 -0.035 -0.002">
  </origin>
  <parent link="head">
  </parent>
  <child link="right_camera_frame">
  </child>
 </joint>
 <link name="right_camera_frame">
  <inertial>
   <mass value="0.001">
   </mass>
   <!-- collocate with parent link and remove mass from it -->
   <origin xyz="-0.075493 -0.034966617 0.02574">
   </origin>
   <inertia ixx="1e-6" ixy="0" ixz="0" iyy="1e-6" iyz="0" izz="1e-6">
   </inertia>
  </inertial>
 </link>
 <joint name="right_camera_optical_frame_joint" type="fixed">
  <origin rpy="-1.5708 0.0 -1.5708" xyz="0 0 0">
  </origin>
  <parent link="right_camera_frame">
  </parent>
  <child link="right_camera_optical_frame">
  </child>
 </joint>
 <link name="right_camera_optical_frame"/>
 <joint name="center_top_led_frame_joint" type="fixed">
  <origin xyz="0.01125 0.0 0.0105">
  </origin>
  <parent link="head">
  </parent>
  <child link="center_top_led_frame">
  </child>
 </joint>
 <link name="center_top_led_frame">
  <inertial>
   <mass value="0.001">
   </mass>
   <!-- collocate with parent link and remove mass from it -->
   <origin rpy="0 0 0" xyz="-0.064243 0.000033383 0.03824">
   </origin>
   <inertia ixx="1e-6" ixy="0" ixz="0" iyy="1e-6" iyz="0" izz="1e-6">
   </inertia>
  </inertial>
 </link>
 <joint name="center_bottom_led_frame_joint" type="fixed">
  <origin xyz="0.01125 0.0 -0.0155">
  </origin>
  <parent link="head">
  </parent>
  <child link="center_bottom_led_frame">
  </child>
 </joint>
 <link name="center_bottom_led_frame">
  <inertial>
   <mass value="0.001">
   </mass>
   <!-- collocate with parent link and remove mass from it -->
   <origin rpy="0 0 0" xyz="-0.064243 0.000033383 0.01224">
   </origin>
   <inertia ixx="1e-6" ixy="0" ixz="0" iyy="1e-6" iyz="0" izz="1e-6">
   </inertia>
  </inertial>
 </link>
 <joint name="left_led_frame_joint" type="fixed">
  <origin rpy="0 -0.15 0.53" xyz="-0.01443 0.07452 0.050346">
  </origin>
  <parent link="head">
  </parent>
  <child link="left_led_frame">
  </child>
 </joint>
 <link name="left_led_frame">
  <inertial>
   <mass value="0.001">
   </mass>
   <!-- collocate with parent link and remove mass from it -->
   <origin rpy="0 -0.15 0.53" xyz="-0.089923 0.074553383 0.078086">
   </origin>
   <inertia ixx="1e-6" ixy="0" ixz="0" iyy="1e-6" iyz="0" izz="1e-6">
   </inertia>
  </inertial>
 </link>
 <joint name="right_led_frame_joint" type="fixed">
  <origin rpy="0 -0.15 -0.53" xyz="-0.01443 -0.07452 0.050346">
  </origin>
  <parent link="head">
  </parent>
  <child link="right_led_frame">
  </child>
 </joint>
 <link name="right_led_frame">
  <inertial>
   <mass value="0.001">
   </mass>
   <!-- collocate with parent link and remove mass from it -->
   <origin rpy="0 -0.15 -0.53" xyz="-0.089923 -0.074486617 0.07908">
   </origin>
   <inertia ixx="1e-6" ixy="0" ixz="0" iyy="1e-6" iyz="0" izz="1e-6">
   </inertia>
  </inertial>
 </link>
 <!-- imu link -->
 <link name="head_imu_link">
  <inertial>
   <mass value="0.001">
   </mass>
   <!-- collocate with parent link and remove mass from it -->
   <origin rpy="0 0 0" xyz="-0.122993 0.035033383 0.02774">
   </origin>
   <inertia ixx="1e-6" ixy="0" ixz="0" iyy="1e-6" iyz="0" izz="1e-6">
   </inertia>
  </inertial>
  <visual>
   <origin rpy="0 0 0" xyz="0 0 0">
   </origin>
   <geometry>
    <box size="0.01 0.01 0.01">
    </box>
   </geometry>
  </visual>
 </link>
 <joint name="head_imu_joint" type="fixed">
  <parent link="head">
  </parent>
  <child link="head_imu_link">
  </child>
  <!-- putting it at the same z-level as the stereo -->
  <origin rpy="0 0 0" xyz="-0.0475 0.035 0.0">
  </origin>
 </joint>
 <gazebo reference="head_imu_link">
  <!-- this is expected to be reparented to head with appropriate offset
         when head_imu_link is reduced by fixed joint reduction -->
  <!-- todo: this is working with gazebo 1.4, need to write a unit test -->
  <sensor name="head_imu_sensor" type="imu">
   <always_on>
    1
   </always_on>
   <update_rate>
    1000.0
   </update_rate>
   <imu>
    <noise>
     <type>
      gaussian
     </type>
     <!-- Noise parameters from Boston Dynamics
               (http://gazebosim.org/wiki/Sensor_noise):
                 rates (rad/s): mean=0, stddev=2e-4
                 accels (m/s/s): mean=0, stddev=1.7e-2
                 rate bias (rad/s): 5e-6 - 1e-5
                 accel bias (m/s/s): 1e-1
               Experimentally, simulation provide rates with noise of
               about 1e-3 rad/s and accels with noise of about 1e-1 m/s/s.
               So we don't expect to see the noise unless number of inner iterations
               are increased.

               We will add bias.  In this model, bias is sampled once for rates
               and once for accels at startup; the sign (negative or positive)
               of each bias is then switched with equal probability.  Thereafter,
               the biases are fixed additive offsets.  We choose
               bias means and stddevs to produce biases close to the provided
               data. -->
     <rate>
      <mean>
       0.0
      </mean>
      <stddev>
       2e-4
      </stddev>
      <bias_mean>
       0.0000075
      </bias_mean>
      <bias_stddev>
       0.0000008
      </bias_stddev>
     </rate>
     <accel>
      <mean>
       0.0
      </mean>
      <stddev>
       1.7e-2
      </stddev>
      <bias_mean>
       0.1
      </bias_mean>
      <bias_stddev>
       0.001
      </bias_stddev>
     </accel>
    </noise>
   </imu>
  </sensor>
 </gazebo>
 <!-- drake feet mods-->
 <frame link="leftFoot" name="l_foot_sole" rpy="0 0 0" xyz="0.067  0 -0.09"/>
 <frame link="rightFoot" name="r_foot_sole" rpy="0 0 0" xyz="0.067 0 -0.09"/>
 <frame link="leftFoot" name="l_foot_toe" rpy="0 0 0" xyz="0.172  0 -0.09"/>
 <frame link="rightFoot" name="r_foot_toe" rpy="0 0 0" xyz="0.172 0 -0.09"/>
 <!-- end drake feet mods-->
 <!-- drake left hand frames-->
 <link name="l_hand_force_torque">
  <inertial>
   <mass value="0.0010280826711148727">
   </mass>
   <origin xyz="0 0 0">
   </origin>
   <inertia ixx="0.00001" ixy="0" ixz="0" iyy="0.00001" iyz="0" izz="0.00001">
   </inertia>
  </inertial>
  <visual>
   <origin rpy="0 0 0" xyz="0 0 0">
   </origin>
   <geometry>
    <box size="0.01 0.01 0.01">
    </box>
   </geometry>
  </visual>
 </link>
 <joint name="l_hand_force_torque_joint" type="fixed">
  <origin rpy="-1.57079632679 0 1.57079632679" xyz="0 0 0">
  </origin>
  <parent link="leftPalm">
  </parent>
  <child link="l_hand_force_torque">
  </child>
 </joint>
 <link name="left_palm">
  <inertial>
   <mass value="0.001">
   </mass>
   <origin xyz="0 0 0">
   </origin>
   <inertia ixx="0.00001" ixy="0" ixz="0" iyy="0.00001" iyz="0" izz="0.00001">
   </inertia>
  </inertial>
  <visual>
   <origin rpy="0 0 0" xyz="0 0 0">
   </origin>
   <geometry>
    <box size="0.01 0.01 0.01">
    </box>
   </geometry>
  </visual>
 </link>
 <joint name="left_valkyrie_hand_joint" type="fixed">
  <origin rpy="1.57079632679 1.57079632679 0" xyz="0.08 0 0">
  </origin>
  <parent link="l_hand_force_torque">
  </parent>
  <child link="left_palm">
  </child>
 </joint>
 <link name="l_hand_face">
  <inertial>
   <mass value="0.0014504132434770935">
   </mass>
   <origin xyz="0 0 0">
   </origin>
   <inertia ixx="0.00001" ixy="0" ixz="0" iyy="0.00001" iyz="0" izz="0.00001">
   </inertia>
  </inertial>
 </link>
 <joint name="l_hand_face_joint" type="fixed">
  <origin rpy="3.14159265359 0 1.57079632679" xyz="0.07 0.0 -0.08">
  </origin>
  <parent link="l_hand_force_torque">
  </parent>
  <child link="l_hand_face">
  </child>
 </joint>
 <!-- end drake left hand frames-->
 <!-- drake right hand frames-->
 <link name="r_hand_force_torque">
  <inertial>
   <mass value="0.00123283121986523">
   </mass>
   <origin xyz="0 0 0">
   </origin>
   <inertia ixx="0.00001" ixy="0" ixz="0" iyy="0.00001" iyz="0" izz="0.00001">
   </inertia>
  </inertial>
  <visual>
   <origin rpy="0 0 0" xyz="0 0 0">
   </origin>
   <geometry>
    <box size="0.01 0.01 0.01">
    </box>
   </geometry>
  </visual>
 </link>
 <joint name="r_hand_force_torque_joint" type="fixed">
  <origin rpy="-1.57079632679 0 -1.57079632679" xyz="0 0 0">
  </origin>
  <parent link="rightPalm">
  </parent>
  <child link="r_hand_force_torque">
  </child>
 </joint>
 <link name="right_palm">
  <inertial>
   <mass value="0.001">
   </mass>
   <origin xyz="0 0 0">
   </origin>
   <inertia ixx="0.00001" ixy="0" ixz="0" iyy="0.00001" iyz="0" izz="0.00001">
   </inertia>
  </inertial>
  <visual>
   <origin rpy="0 0 0" xyz="0 0 0">
   </origin>
   <geometry>
    <box size="0.01 0.01 0.01">
    </box>
   </geometry>
  </visual>
 </link>
 <joint name="right_valkyrie_hand_joint" type="fixed">
  <origin rpy="0 -1.57079632679 -1.57079632679" xyz="0.08 0 0">
  </origin>
  <parent link="r_hand_force_torque">
  </parent>
  <child link="right_palm">
  </child>
 </joint>
 <link name="r_hand_face">
  <inertial>
   <mass value="0.0017441260968978">
   </mass>
   <origin xyz="0 0 0">
   </origin>
   <inertia ixx="0.00001" ixy="0" ixz="0" iyy="0.00001" iyz="0" izz="0.00001">
   </inertia>
  </inertial>
 </link>
 <joint name="r_hand_face_joint" type="fixed">
  <origin rpy="0 0 -1.57079632679" xyz="0.07 0 0.08">
  </origin>
  <parent link="r_hand_force_torque">
  </parent>
  <child link="r_hand_face">
  </child>
 </joint>
 <!-- end drake right hand frames-->
 <!-- drake collision free groups-->
 <collision_filter_group name="feet">
  <member link="leftFoot">
  </member>
  <member link="rightFoot">
  </member>
  <ignored_collision_filter_group collision_filter_group="feet">
  </ignored_collision_filter_group>
 </collision_filter_group>
 <collision_filter_group name="core">
  <member link="torso">
  </member>
  <member link="torsoYawLink">
  </member>
  <member link="torsoPitchLink">
  </member>
  <member link="pelvis">
  </member>
  <member link="lowerNeckPitchLink">
  </member>
  <member link="neckYawLink">
  </member>
  <member link="upperNeckPitchLink">
  </member>
  <member link="head">
  </member>
  <ignored_collision_filter_group collision_filter_group="core">
  </ignored_collision_filter_group>
 </collision_filter_group>
 <collision_filter_group name="ignore_core">
  <member link="rightShoulderRollLink">
  </member>
  <member link="leftShoulderRollLink">
  </member>
  <member link="rightShoulderPitchLink">
  </member>
  <member link="leftShoulderPitchLink">
  </member>
  <ignored_collision_filter_group collision_filter_group="core">
  </ignored_collision_filter_group>
 </collision_filter_group>
 <collision_filter_group name="r_uleg">
  <member link="rightHipYawLink">
  </member>
  <member link="rightHipRollLink">
  </member>
  <member link="rightHipPitchLink">
  </member>
  <ignored_collision_filter_group collision_filter_group="core">
  </ignored_collision_filter_group>
  <ignored_collision_filter_group collision_filter_group="r_uleg">
  </ignored_collision_filter_group>
  <ignored_collision_filter_group collision_filter_group="l_uleg">
  </ignored_collision_filter_group>
 </collision_filter_group>
 <collision_filter_group name="l_uleg">
  <member link="leftHipYawLink">
  </member>
  <member link="leftHipRollLink">
  </member>
  <member link="leftHipPitchLink">
  </member>
  <ignored_collision_filter_group collision_filter_group="core">
  </ignored_collision_filter_group>
  <ignored_collision_filter_group collision_filter_group="r_uleg">
  </ignored_collision_filter_group>
  <ignored_collision_filter_group collision_filter_group="l_uleg">
  </ignored_collision_filter_group>
 </collision_filter_group>
 <collision_filter_group name="r_leg">
  <member link="rightKneePitchLink">
  </member>
  <member link="rightAnklePitchLink">
  </member>
  <member link="rightFoot">
  </member>
  <ignored_collision_filter_group collision_filter_group="r_leg">
  </ignored_collision_filter_group>
  <ignored_collision_filter_group collision_filter_group="r_uleg">
  </ignored_collision_filter_group>
 </collision_filter_group>
 <collision_filter_group name="l_leg">
  <member link="leftKneePitchLink">
  </member>
  <member link="leftAnklePitchLink">
  </member>
  <member link="leftFoot">
  </member>
  <ignored_collision_filter_group collision_filter_group="l_leg">
  </ignored_collision_filter_group>
  <ignored_collision_filter_group collision_filter_group="l_uleg">
  </ignored_collision_filter_group>
 </collision_filter_group>
 <collision_filter_group name="r_arm">
  <member link="rightShoulderPitchLink">
  </member>
  <member link="rightShoulderRollLink">
  </member>
  <member link="rightShoulderYawLink">
  </member>
  <member link="rightElbowPitchLink">
  </member>
  <member link="rightForearmLink">
  </member>
  <member link="rightWristRollLink">
  </member>
  <member link="rightPalm">
  </member>
  <ignored_collision_filter_group collision_filter_group="r_arm">
  </ignored_collision_filter_group>
 </collision_filter_group>
 <collision_filter_group name="l_arm">
  <member link="leftShoulderPitchLink">
  </member>
  <member link="leftShoulderRollLink">
  </member>
  <member link="leftShoulderYawLink">
  </member>
  <member link="leftElbowPitchLink">
  </member>
  <member link="leftForearmLink">
  </member>
  <member link="leftWristRollLink">
  </member>
  <member link="leftPalm">
  </member>
  <ignored_collision_filter_group collision_filter_group="l_arm">
  </ignored_collision_filter_group>
 </collision_filter_group>
 <!-- end drake collision free groups-->
</robot>
